Workbook

Sheet คำแนะนำ
B2: ฐานข้อมูลราคา งานจดทะเบียนรถ (Auto-Price Workbook)
B5: โครงสร้างไฟล์นี้ออกแบบเป็น "ฐานข้อมูล" ง่าย ๆ ใน Excel แบ่งเป็น 2 กลุ่มชีต:
B7: 1) ชีตตารางราคา/มาสเตอร์ (Fee_... และ M_...) เก็บ "รายการราคา" แยกตามประเภทรถ/ยี่ห้อ
B8: เหมือนเป็นตารางฐานข้อมูลที่โปรแกรมเมอร์จะ import เข้าโปรแกรมทีหลัง
B9: -> แก้ตัวเลขราคาที่ชีตเหล่านี้ที่เดียว ราคาทุกจุดในไฟล์จะอัปเดตตาม
B11: 2) ชีต "บันทึกงาน" คือหน้ากรอกงานจริง 1 แถว = 1 คัน/1 งาน
B12: ช่องพื้นเหลือง/ตัวอักษรสีน้ำเงิน = ช่องที่ต้องกรอกเอง (มี dropdown ให้เลือก)
B13: ช่องตัวอักษรสีดำ = สูตรคำนวณราคาอัตโนมัติ ห้ามพิมพ์ทับ
B15: วิธีที่ราคา "ขึ้นอัตโนมัติ": ทุกครั้งที่เลือก ประเภทรถ/ยี่ห้อ/จังหวัด ในชีตบันทึกงาน
B16: สูตร INDEX/MATCH จะไปค้นราคาในชีต Fee_... ให้เอง (หลักการเดียวกับ VLOOKUP) แล้วเติมราคาให้
B18: ชีตที่ยังไม่มีข้อมูลครบ (ต้องกรอกเพิ่มเอง ตามที่ยังไม่ได้ให้ข้อมูลมา):
B19: - Fee_ตรวจรถ_ตจว: ค่าตรวจรถต่างจังหวัด รายจังหวัด (เตรียมตารางว่างไว้ให้ 77 จังหวัดแล้ว)
... B24: โครงสร้างคีย์ค้นหา (Key) ใช้รูปแบบ "ประเภทรถ|ยี่ห้อ" หรือ "จังหวัด|ประเภทรถ" คั่นด้วย |

Sheet M_ประเภทรถ
A1: ประเภทรถ (13 รายการตามระบบเดิม) | B1: หมวด
A2: รย.12-น้อยกว่า 300cc | B2: รถจักรยานยนต์
A3: รย.12-300-799cc | B3: รถจักรยานยนต์
A4: รย.12-800-999cc | B4: รถจักรยานยนต์
A5: รย.12-1000cc ขึ้นไป | B5: รถจักรยานยนต์
A6: รย.1-เก๋ง 2 ตอน | B6: รถยนต์
A7: รย.1-นั่ง 2 ตอน | B7: รถยนต์
A8: รย.1-นั่ง 3 ตอน | B8: รถยนต์
A9: รย.2-นั่ง 2 แถว | B9: รถยนต์
A10: รย.2-นั่ง 4 ตอน | B10: รถยนต์
A11: รย.3-กระบะบรรทุก | B11: รถยนต์
A12: รย.3-กระบะบรรทุกมีหลังคา | B12: รถยนต์
... A14: รย.3-ตู้บรรทุก | B14: รถยนต์

Sheet M_ยี่ห้อ
A1: ยี่ห้อ | B1: หมายเหตุ
A2: อื่นๆ | B2: ยี่ห้อทั่วไปทั้งหมด (ราคาตามอัตรามาตรฐาน)
A3: Benz | B3: มีอัตราตัดบัญชี/แจ้งย้าย/ตรวจรถแยกเฉพาะ (เฉพาะ รย.1-เก๋ง 2 ตอน)
A4: BMW | B4: มีอัตราตัดบัญชี/แจ้งย้าย/ตรวจรถแยกเฉพาะ (เฉพาะ รย.1-เก๋ง 2 ตอน)
A5: Lexus | B5: มีอัตราตัดบัญชี/แจ้งย้าย/ตรวจรถแยกเฉพาะ (เฉพาะ รย.1-เก๋ง 2 ตอน)
A6: Volvo | B6: มีอัตราตัดบัญชี/แจ้งย้าย/ตรวจรถแยกเฉพาะ (เฉพาะ รย.1-เก๋ง 2 ตอน)

Sheet M_จังหวัด
A1: จังหวัด (77 จังหวัด)
A2: กรุงเทพมหานคร
A3: กระบี่
A4: กาญจนบุรี
A5: กาฬสินธุ์
A6: กำแพงเพชร
A7: ขอนแก่น
A8: จันทบุรี
A9: ฉะเชิงเทรา
A10: ชลบุรี
A11: ชัยนาท
A12: ชัยภูมิ
... A78: อุบลราชธานี

Sheet Fee_ตัดบัญชี
A1: ประเภทรถ | B1: ยี่ห้อ | C1: Key (ประเภทรถ|ยี่ห้อ) | D1: ค่าตัดบัญชี (บาท/No bill)
A2: รย.12-น้อยกว่า 300cc | B2: อื่นๆ | C2: =A2&"|"&B2 -> รย.12-น้อยกว่า 300cc|อื่นๆ | D2: 12
A3: รย.12-300-799cc | B3: อื่นๆ | C3: =A3&"|"&B3 -> รย.12-300-799cc|อื่นๆ | D3: 12
A4: รย.12-800-999cc | B4: อื่นๆ | C4: =A4&"|"&B4 -> รย.12-800-999cc|อื่นๆ | D4: 12
A5: รย.12-1000cc ขึ้นไป | B5: อื่นๆ | C5: =A5&"|"&B5 -> รย.12-1000cc ขึ้นไป|อื่นๆ | D5: 12
A6: รย.1-เก๋ง 2 ตอน | B6: อื่นๆ | C6: =A6&"|"&B6 -> รย.1-เก๋ง 2 ตอน|อื่นๆ | D6: 20
A7: รย.1-เก๋ง 2 ตอน | B7: Benz | C7: =A7&"|"&B7 -> รย.1-เก๋ง 2 ตอน|Benz | D7: 20
A8: รย.1-เก๋ง 2 ตอน | B8: BMW | C8: =A8&"|"&B8 -> รย.1-เก๋ง 2 ตอน|BMW | D8: 20
A9: รย.1-เก๋ง 2 ตอน | B9: Lexus | C9: =A9&"|"&B9 -> รย.1-เก๋ง 2 ตอน|Lexus | D9: 20
A10: รย.1-เก๋ง 2 ตอน | B10: Volvo | C10: =A10&"|"&B10 -> รย.1-เก๋ง 2 ตอน|Volvo | D10: 20
A11: รย.1-นั่ง 2 ตอน | B11: อื่นๆ | C11: =A11&"|"&B11 -> รย.1-นั่ง 2 ตอน|อื่นๆ | D11: 20
A12: รย.1-นั่ง 3 ตอน | B12: อื่นๆ | C12: =A12&"|"&B12 -> รย.1-นั่ง 3 ตอน|อื่นๆ | D12: 20
A13: รย.2-นั่ง 2 แถว | B13: อื่นๆ | C13: =A13&"|"&B13 -> รย.2-นั่ง 2 แถว|อื่นๆ | D13: 50
... A19: นำรถมาตรวจ | B19: อื่นๆ | C19: =A19&"|"&B19 -> นำรถมาตรวจ|อื่นๆ | D19: 20

Sheet Fee_แจ้งย้าย
A1: ประเภทรถ | B1: ยี่ห้อ | C1: Key (ประเภทรถ|ยี่ห้อ) | D1: ค่าแจ้งย้าย (บาท/No bill)
A2: รย.12-น้อยกว่า 300cc | B2: อื่นๆ | C2: =A2&"|"&B2 -> รย.12-น้อยกว่า 300cc|อื่นๆ | D2: 20
A3: รย.12-300-799cc | B3: อื่นๆ | C3: =A3&"|"&B3 -> รย.12-300-799cc|อื่นๆ | D3: 20
A4: รย.12-800-999cc | B4: อื่นๆ | C4: =A4&"|"&B4 -> รย.12-800-999cc|อื่นๆ | D4: 20
A5: รย.12-1000cc ขึ้นไป | B5: อื่นๆ | C5: =A5&"|"&B5 -> รย.12-1000cc ขึ้นไป|อื่นๆ | D5: 20
A6: รย.1-เก๋ง 2 ตอน | B6: อื่นๆ | C6: =A6&"|"&B6 -> รย.1-เก๋ง 2 ตอน|อื่นๆ | D6: 30
A7: รย.1-เก๋ง 2 ตอน | B7: Benz | C7: =A7&"|"&B7 -> รย.1-เก๋ง 2 ตอน|Benz | D7: 30
A8: รย.1-เก๋ง 2 ตอน | B8: BMW | C8: =A8&"|"&B8 -> รย.1-เก๋ง 2 ตอน|BMW | D8: 30
A9: รย.1-เก๋ง 2 ตอน | B9: Lexus | C9: =A9&"|"&B9 -> รย.1-เก๋ง 2 ตอน|Lexus | D9: 30
A10: รย.1-เก๋ง 2 ตอน | B10: Volvo | C10: =A10&"|"&B10 -> รย.1-เก๋ง 2 ตอน|Volvo | D10: 30
A11: รย.1-นั่ง 2 ตอน | B11: อื่นๆ | C11: =A11&"|"&B11 -> รย.1-นั่ง 2 ตอน|อื่นๆ | D11: 30
A12: รย.1-นั่ง 3 ตอน | B12: อื่นๆ | C12: =A12&"|"&B12 -> รย.1-นั่ง 3 ตอน|อื่นๆ | D12: 30
A13: รย.2-นั่ง 2 แถว | B13: อื่นๆ | C13: =A13&"|"&B13 -> รย.2-นั่ง 2 แถว|อื่นๆ | D13: 30
... A19: นำรถมาตรวจ | B19: อื่นๆ | C19: =A19&"|"&B19 -> นำรถมาตรวจ|อื่นๆ | D19: 30
A21: หมายเหตุ: กรณีแจ้งย้าย จะมีค่า Bill เพิ่มอีกคันละ 5 บาท (คำนวณอัตโนมัติในชีตบันทึกงาน)

Sheet Fee_ตรวจรถ_กทม
A1: ประเภทรถ | B1: ยี่ห้อ | C1: Key (ประเภทรถ|ยี่ห้อ) | D1: ค่าตรวจรถ กทม. (บาท)
A2: รย.12-น้อยกว่า 300cc | B2: อื่นๆ | C2: =A2&"|"&B2 -> รย.12-น้อยกว่า 300cc|อื่นๆ | D2: 50
A3: รย.12-300-799cc | B3: อื่นๆ | C3: =A3&"|"&B3 -> รย.12-300-799cc|อื่นๆ | D3: 300
A4: รย.12-800-999cc | B4: อื่นๆ | C4: =A4&"|"&B4 -> รย.12-800-999cc|อื่นๆ | D4: 500
A5: รย.12-1000cc ขึ้นไป | B5: อื่นๆ | C5: =A5&"|"&B5 -> รย.12-1000cc ขึ้นไป|อื่นๆ | D5: 1000
A6: รย.1-เก๋ง 2 ตอน | B6: อื่นๆ | C6: =A6&"|"&B6 -> รย.1-เก๋ง 2 ตอน|อื่นๆ | D6: 150
A7: รย.1-เก๋ง 2 ตอน | B7: Benz | C7: =A7&"|"&B7 -> รย.1-เก๋ง 2 ตอน|Benz | D7: 200
A8: รย.1-เก๋ง 2 ตอน | B8: BMW | C8: =A8&"|"&B8 -> รย.1-เก๋ง 2 ตอน|BMW | D8: 200
A9: รย.1-เก๋ง 2 ตอน | B9: Lexus | C9: =A9&"|"&B9 -> รย.1-เก๋ง 2 ตอน|Lexus | D9: 200
A10: รย.1-เก๋ง 2 ตอน | B10: Volvo | C10: =A10&"|"&B10 -> รย.1-เก๋ง 2 ตอน|Volvo | D10: 200
A11: รย.1-นั่ง 2 ตอน | B11: อื่นๆ | C11: =A11&"|"&B11 -> รย.1-นั่ง 2 ตอน|อื่นๆ | D11: 300
A12: รย.1-นั่ง 3 ตอน | B12: อื่นๆ | C12: =A12&"|"&B12 -> รย.1-นั่ง 3 ตอน|อื่นๆ | D12: 300
A13: รย.2-นั่ง 2 แถว | B13: อื่นๆ | C13: =A13&"|"&B13 -> รย.2-นั่ง 2 แถว|อื่นๆ | D13: 500
... A19: นำรถมาตรวจ | B19: อื่นๆ | C19: =A19&"|"&B19 -> นำรถมาตรวจ|อื่นๆ | D19: 0
A21: หมายเหตุ: ใช้เฉพาะกรณีเป็นงานตัดบัญชี (Step 2) ตามเงื่อนไขที่ให้มา

Sheet Fee_ตรวจรถ_ตจว
A1: จังหวัด | B1: ประเภทรถ | C1: Key (จังหวัด|ประเภทรถ) | D1: ค่าตรวจรถ ต่างจังหวัด (บาท) | F1: ยังไม่มีข้อมูลราคา - กรอกคอลัมน์ D เพิ่มเองตามจังหวัด (ค่าว่าง = ยังไม่กรอก = คำนวณเป็น 0)
A2: กรุงเทพมหานคร | B2: รย.12-น้อยกว่า 300cc | C2: =A2&"|"&B2 -> กรุงเทพมหานคร|รย.12-น้อยกว่า 300cc
A3: กรุงเทพมหานคร | B3: รย.12-300-799cc | C3: =A3&"|"&B3 -> กรุงเทพมหานคร|รย.12-300-799cc
A4: กรุงเทพมหานคร | B4: รย.12-800-999cc | C4: =A4&"|"&B4 -> กรุงเทพมหานคร|รย.12-800-999cc
A5: กรุงเทพมหานคร | B5: รย.12-1000cc ขึ้นไป | C5: =A5&"|"&B5 -> กรุงเทพมหานคร|รย.12-1000cc ขึ้นไป
A6: กรุงเทพมหานคร | B6: รย.1-เก๋ง 2 ตอน | C6: =A6&"|"&B6 -> กรุงเทพมหานคร|รย.1-เก๋ง 2 ตอน
A7: กรุงเทพมหานคร | B7: รย.1-นั่ง 2 ตอน | C7: =A7&"|"&B7 -> กรุงเทพมหานคร|รย.1-นั่ง 2 ตอน
A8: กรุงเทพมหานคร | B8: รย.1-นั่ง 3 ตอน | C8: =A8&"|"&B8 -> กรุงเทพมหานคร|รย.1-นั่ง 3 ตอน
A9: กรุงเทพมหานคร | B9: รย.2-นั่ง 2 แถว | C9: =A9&"|"&B9 -> กรุงเทพมหานคร|รย.2-นั่ง 2 แถว
A10: กรุงเทพมหานคร | B10: รย.2-นั่ง 4 ตอน | C10: =A10&"|"&B10 -> กรุงเทพมหานคร|รย.2-นั่ง 4 ตอน
A11: กรุงเทพมหานคร | B11: รย.3-กระบะบรรทุก | C11: =A11&"|"&B11 -> กรุงเทพมหานคร|รย.3-กระบะบรรทุก
A12: กรุงเทพมหานคร | B12: รย.3-กระบะบรรทุกมีหลังคา | C12: =A12&"|"&B12 -> กรุงเทพมหานคร|รย.3-กระบะบรรทุกมีหลังคา
A13: กรุงเทพมหานคร | B13: รย.3-กระบะบรรทุกมีหลังคาแหนบ | C13: =A13&"|"&B13 -> กรุงเทพมหานคร|รย.3-กระบะบรรทุกมีหลังคาแหนบ
... A1002: อุบลราชธานี | B1002: รย.3-ตู้บรรทุก | C1002: =A1002&"|"&B1002 -> อุบลราชธานี|รย.3-ตู้บรรทุก

Sheet Fee_รถยนต์_Bill
A1: รายการ | B1: ราคา (บาท) | C1: หมายเหตุ
A2: ค่าคำขอ (ปกติ) | B2: 5 | C2: ใช้เมื่อจดในจังหวัดภูมิลำเนาของเจ้าของรถ
A3: ค่าคำขอ (ขอใช้จังหวัดอื่น) | B3: 10 | C3: ใช้เมื่อจังหวัดที่จดทะเบียน (Step1) ต่างจากจังหวัดเจ้าของรถ
A4: ค่าธรรมเนียมอื่นๆ (ขอใช้จังหวัดอื่น) | B4: 20 | C4: เพิ่มเฉพาะกรณีขอใช้จังหวัดอื่น
A5: ค่าตรวจสภาพรถ (Step4) | B5: 50
A6: ค่าแผ่นป้ายทะเบียนรถ | B6: 200
A7: ค่าใบคู่มือการจดทะเบียน | B7: 100
A8: ค่าภาษีรถยนต์ | B8: 0 | C8: ยังไม่ได้กำหนดสูตร (อิง CC/น้ำหนัก/ประเภทเชื้อเพลิง) - กรอกเองต่อคันในชีตบันทึกงาน จนกว่าจะได้เงื่อนไข
A9: ค่าขอใช้เลขทะเบียน - เลขประมูล | B9: 1500
A10: ค่าขอใช้เลขทะเบียน - ไม่ใช่เลขประมูล | B10: 500
A11: ค่าทำแผ่นป้ายทะเบียนใหม่ - ป้ายขาวดำ | B11: 200
A12: ค่าทำแผ่นป้ายทะเบียนใหม่ - ป้ายประมูล | B12: 1200
A13: ค่าย้ายออกต่างจังหวัด | B13: 50 | C13: กรณีจดพร้อมย้ายออกไปต่างจังหวัด

Sheet Fee_รถยนต์_NoBill
A1: รายการ | B1: ราคา (บาท) | C1: หมายเหตุ
A2: ค่าอากร (ปกติ) | B2: 10
A3: ค่าอากร (ทำเพิ่มเติมเกิน 1 รายการ) | B3: 30
A4: ลงขัน - รย.1-เก๋ง 2 ตอน | B4: 50
A5: ลงขัน - รย.1-นั่ง 2 ตอน | B5: 100
A6: ลงขัน - รย.1-นั่ง 3 ตอน | B6: 50
A7: ลงขัน - รย.2-นั่ง 2 แถว | B7: 50
A8: ลงขัน - รย.2-นั่ง 4 ตอน | B8: 50
A9: ลงขัน - รย.3-กระบะบรรทุก | B9: 50
A10: ลงขัน - รย.3-กระบะบรรทุกมีหลังคา | B10: 50
A11: ลงขัน - รย.3-กระบะบรรทุกมีหลังคาแหนบ | B11: 50 | C11: ไม่มีราคาลงขันในข้อมูลที่ให้มา - กรอกเพิ่มเอง
A12: ลงขัน - รย.3-ตู้บรรทุก | B12: 50
A13: งานด่วนเพิ่ม (ต่อคัน) | B13: 100

Sheet Fee_จยย_Bill
A1: รายการ | B1: ราคา (บาท) | C1: หมายเหตุ
A2: ค่าคำขอ (ปกติ) | B2: 5 | C2: ใช้เมื่อจดในจังหวัดภูมิลำเนาของเจ้าของรถ
A3: ค่าคำขอ (ขอใช้จังหวัดอื่น) | B3: 10 | C3: ใช้เมื่อจังหวัดที่จดทะเบียน (Step1) ต่างจากจังหวัดเจ้าของรถ
A4: ค่าธรรมเนียมอื่นๆ (ขอใช้จังหวัดอื่น) | B4: 20 | C4: เพิ่มเฉพาะกรณีขอใช้จังหวัดอื่น
A5: ค่าตรวจสภาพรถ (จยย.) | B5: 100
A6: ค่าแผ่นป้ายทะเบียน | B6: 100
A7: ค่าใบคู่มือจดทะเบียน | B7: 100
A8: ค่าภาษีรถจักรยานยนต์ | B8: 100

Sheet Fee_จยย_NoBill
A1: รายการ | B1: ราคา (บาท) | C1: หมายเหตุ
A2: ค่าอากร (ปกติ) | B2: 10
A3: ค่าอากร (ทำเพิ่มเติมเกิน 1 รายการ) | B3: 30
A4: ลงขัน - รย.12 ทุกประเภท (CC) | B4: 40 | C4: ข้อมูลต้นทางระบุ 40 บาทเท่ากันทุกช่วง CC
A5: ลงขันด่วนเพิ่ม (ต่อคัน) | B5: 50

Sheet บันทึกงาน
A1: ลำดับ | B1: วันที่รับงาน | C1: ชื่อลูกค้า | D1: เลขตัวถัง | E1: เลขเครื่อง | F1: ยี่ห้อ | G1: ประเภทเชื้อเพลิง | H1: ขนาด CC | I1: น้ำหนักรถ (กก.) | J1: สี | K1: ประเภทรถ | L1: จังหวัดที่จดทะเบียน | M1: จังหวัดเจ้าของรถ | N1: ขอใช้จังหวัดอื่น | O1: Step2: ประเภทงาน | P1: ค่าตัดบัญชี | Q1: ค่าแจ้งย้าย (No bill) | R1: ค่าแจ้งย้าย (Bill) | S1: Step3: สถานที่ตรวจรถ | T1: ค่าตรวจรถ | U1: ประเภทยานพาหนะ | V1: ค่าคำขอ | W1: ค่าธรรมเนียมอื่นๆ | X1: ค่าตรวจสภาพรถ | Y1: ค่าแผ่นป้ายทะเบียนรถ | Z1: ค่าใบคู่มือจดทะเบียน | AA1: ค่าภาษีรถ (กรอกเอง/รถยนต์) | AB1: ขอใช้เลขทะเบียน | AC1: ค่าขอใช้เลขทะเบียน | AD1: ทำแผ่นป้ายใหม่ | AE1: ค่าทำแผ่นป้ายใหม่ | AF1: ย้ายออกต่างจังหวัด | AG1: ค่าย้ายออก | AH1: รวม Bill (Step4) | AI1: ทำเกิน 1 รายการ | AJ1: ค่าอากร | AK1: ค่าลงขัน | AL1: งานด่วน/ลงขันด่วน | AM1: ค่าลงขันด่วนเพิ่ม | AN1: รวม No bill | AO1: รวมราคาทั้งหมด | AP1: วันที่รับใบเสร็จ | AQ1: รูปหลักฐานใบเสร็จ | AR1: วันที่รับเล่ม | AS1: รูปหลักฐานเล่ม | AT1: วันที่รับป้าย | AU1: รูปหลักฐานป้าย | AV1: วันที่ส่งงานลูกค้า | AW1: รูปหลักฐานส่งงาน | AX1: วันที่วางบิล (Step7) | AY1: วันที่รับเงิน/เลขใบกำกับ (Step8) | AZ1: หมายเหตุ | BA1: BrandForLookup (ห้ามแก้) | BB1: KeyTypeBrand (ห้ามแก้)
A2: =IF($K2="","",ROW()-1) -> 1 | B2: 2569-09-17 | C2: คุณสมชาย ใจดี | D2: MRHGD1234567890 | E2: K12A3456789 | F2: Toyota | G2: น้ำมัน | H2: 1998 | I2: 1500 | J2: ขาว | K2: รย.1-เก๋ง 2 ตอน | L2: กรุงเทพมหานคร | M2: กรุงเทพมหานคร | N2: =IF(OR(L2="",M2=""),"",IF(L2<>M2,"ใช่","ไม่ใช่")) -> ไม่ใช่ | O2: ตัดบัญชี | P2: =IF($K2="","",IF(O2="ตัดบัญชี",IFERROR(INDEX(Fee_ตัดบัญชี!$D:$D,MATCH(BB2,Fee_ตัดบัญชี!$C:$C,0)),0),0)) -> 20 | Q2: =IF($K2="","",IF(O2="แจ้งย้าย",IFERROR(INDEX(Fee_แจ้งย้าย!$D:$D,MATCH(BB2,Fee_แจ้งย้าย!$C:$C,0)),0),0)) -> 0 | R2: =IF($K2="","",IF(O2="แจ้งย้าย",5,0)) -> 0 | S2: กทม. | T2: =IF($K2="","",IF(O2<>"ตัดบัญชี",0,IF(S2="กทม.",IFERROR(INDEX(Fee_ตรวจรถ_กทม!$D:$D,MATCH(BB2,Fee_ตรวจรถ_กทม!$C:$C,0)),0),IF(S2="ต่างจังหวัด",IFERROR(INDEX(Fee_ตรวจรถ_ตจว!$D:$D,MATCH(L2&"|"&K2,Fee_ตรวจรถ_ตจว!$C:$C,0)),0),0)))) -> 150 | U2: =IF($K2="","",IF(LEFT(K2,5)="รย.12","รถจักรยานยนต์","รถยนต์")) -> รถยนต์ | V2: =IF($K2="","",IF(U2="รถยนต์",IF(N2="ใช่",INDEX(Fee_รถยนต์_Bill!$B:$B,MATCH("ค่าคำขอ (ขอใช้จังหวัดอื่น)",Fee_รถยนต์_Bill!$A:$A,0)),INDEX(Fee_รถยนต์_Bill!$B:$B,MATCH("ค่าคำขอ (ปกติ)",Fee_รถยนต์_Bill!$A:$A,0))),IF(N2="ใช่",INDEX(Fee_จยย_Bill!$B:$B,MATCH("ค่าคำขอ (ขอใช้จังหวัดอื่น)",Fee_จยย_Bill!$A:$A,0)),INDEX(Fee_จยย_Bill!$B:$B,MATCH("ค่าคำขอ (ปกติ)",Fee_จยย_Bill!$A:$A,0))))) -> 5 | W2: =IF($K2="","",IF(N2="ใช่",IF(U2="รถยนต์",INDEX(Fee_รถยนต์_Bill!$B:$B,MATCH("ค่าธรรมเนียมอื่นๆ (ขอใช้จังหวัดอื่น)",Fee_รถยนต์_Bill!$A:$A,0)),INDEX(Fee_จยย_Bill!$B:$B,MATCH("ค่าธรรมเนียมอื่นๆ (ขอใช้จังหวัดอื่น)",Fee_จยย_Bill!$A:$A,0))),0)) -> 0 | X2: =IF($K2="","",IF(U2="รถยนต์",INDEX(Fee_รถยนต์_Bill!$B:$B,MATCH("ค่าตรวจสภาพรถ (Step4)",Fee_รถยนต์_Bill!$A:$A,0)),INDEX(Fee_จยย_Bill!$B:$B,MATCH("ค่าตรวจสภาพรถ (จยย.)",Fee_จยย_Bill!$A:$A,0)))) -> 50 | Y2: =IF($K2="","",IF(U2="รถยนต์",INDEX(Fee_รถยนต์_Bill!$B:$B,MATCH("ค่าแผ่นป้ายทะเบียนรถ",Fee_รถยนต์_Bill!$A:$A,0)),INDEX(Fee_จยย_Bill!$B:$B,MATCH("ค่าแผ่นป้ายทะเบียน",Fee_จยย_Bill!$A:$A,0)))) -> 200 | Z2: =IF($K2="","",IF(U2="รถยนต์",INDEX(Fee_รถยนต์_Bill!$B:$B,MATCH("ค่าใบคู่มือการจดทะเบียน",Fee_รถยนต์_Bill!$A:$A,0)),INDEX(Fee_จยย_Bill!$B:$B,MATCH("ค่าใบคู่มือจดทะเบียน",Fee_จยย_Bill!$A:$A,0)))) -> 100 | AA2: 0 | AB2: ไม่ใช่เลขประมูล | AC2: =IF($K2="","",IF(AB2="เลขประมูล",INDEX(Fee_รถยนต์_Bill!$B:$B,MATCH("ค่าขอใช้เลขทะเบียน - เลขประมูล",Fee_รถยนต์_Bill!$A:$A,0)),IF(AB2="ไม่ใช่เลขประมูล",INDEX(Fee_รถยนต์_Bill!$B:$B,MATCH("ค่าขอใช้เลขทะเบียน - ไม่ใช่เลขประมูล",Fee_รถยนต์_Bill!$A:$A,0)),0))) -> 500 | AD2: ไม่มี | AE2: =IF($K2="","",IF(AD2="ป้ายขาวดำ",INDEX(Fee_รถยนต์_Bill!$B:$B,MATCH("ค่าทำแผ่นป้ายทะเบียนใหม่ - ป้ายขาวดำ",Fee_รถยนต์_Bill!$A:$A,0)),IF(AD2="ป้ายประมูล",INDEX(Fee_รถยนต์_Bill!$B:$B,MATCH("ค่าทำแผ่นป้ายทะเบียนใหม่ - ป้ายประมูล",Fee_รถยนต์_Bill!$A:$A,0)),0))) -> 0 | AF2: ไม่ใช่ | AG2: =IF($K2="","",IF(AF2="ใช่",INDEX(Fee_รถยนต์_Bill!$B:$B,MATCH("ค่าย้ายออกต่างจังหวัด",Fee_รถยนต์_Bill!$A:$A,0)),0)) -> 0 | AH2: =IF($K2="","",SUM(V2:AG2)) -> 855 | AI2: ไม่ใช่ | AJ2: =IF($K2="","",IF(U2="รถยนต์",IF(AI2="ใช่",INDEX(Fee_รถยนต์_NoBill!$B:$B,MATCH("ค่าอากร (ทำเพิ่มเติมเกิน 1 รายการ)",Fee_รถยนต์_NoBill!$A:$A,0)),INDEX(Fee_รถยนต์_NoBill!$B:$B,MATCH("ค่าอากร (ปกติ)",Fee_รถยนต์_NoBill!$A:$A,0))),IF(AI2="ใช่",INDEX(Fee_จยย_NoBill!$B:$B,MATCH("ค่าอากร (ทำเพิ่มเติมเกิน 1 รายการ)",Fee_จยย_NoBill!$A:$A,0)),INDEX(Fee_จยย_NoBill!$B:$B,MATCH("ค่าอากร (ปกติ)",Fee_จยย_NoBill!$A:$A,0))))) -> 10 | AK2: =IF($K2="","",IF(U2="รถยนต์",IFERROR(INDEX(Fee_รถยนต์_NoBill!$B:$B,MATCH("ลงขัน - "&K2,Fee_รถยนต์_NoBill!$A:$A,0)),0),IFERROR(INDEX(Fee_จยย_NoBill!$B:$B,MATCH("ลงขัน - รย.12 ทุกประเภท (CC)",Fee_จยย_NoBill!$A:$A,0)),0))) -> 50 | AL2: ไม่ใช่ | AM2: =IF($K2="","",IF(AL2="ใช่",IF(U2="รถยนต์",INDEX(Fee_รถยนต์_NoBill!$B:$B,MATCH("งานด่วนเพิ่ม (ต่อคัน)",Fee_รถยนต์_NoBill!$A:$A,0)),INDEX(Fee_จยย_NoBill!$B:$B,MATCH("ลงขันด่วนเพิ่ม (ต่อคัน)",Fee_จยย_NoBill!$A:$A,0))),0)) -> 0 | AN2: =IF($K2="","",SUM(AJ2:AM2)) -> 60 | AO2: =IF($K2="","",P2+Q2+R2+T2+AH2+AN2) -> 1085 | AP2: 2569-09-20 | AQ2: receipt_001.jpg | AR2: 2569-09-25 | AS2: book_001.jpg | AT2: 2569-09-25 | AU2: plate_001.jpg | AV2: 2569-09-26 | AW2: delivery_001.jpg | AX2: 2569-09-30 | AY2: 2569-10-05 | AZ2: ตัวอย่างแถวสาธิต - แก้ไข/ลบได้ | BA2: =IF($K2="","",IF(AND(K2="รย.1-เก๋ง 2 ตอน",OR(F2="Benz",F2="BMW",F2="Lexus",F2="Volvo")),F2,"อื่นๆ")) -> อื่นๆ | BB2: =IF($K2="","",K2&"|"&BA2) -> รย.1-เก๋ง 2 ตอน|อื่นๆ
A3: =IF($K3="","",ROW()-1) | N3: =IF(OR(L3="",M3=""),"",IF(L3<>M3,"ใช่","ไม่ใช่")) | P3: =IF($K3="","",IF(O3="ตัดบัญชี",IFERROR(INDEX(Fee_ตัดบัญชี!$D:$D,MATCH(BB3,Fee_ตัดบัญชี!$C:$C,0)),0),0)) | Q3: =IF($K3="","",IF(O3="แจ้งย้าย",IFERROR(INDEX(Fee_แจ้งย้าย!$D:$D,MATCH(BB3,Fee_แจ้งย้าย!$C:$C,0)),0),0)) | R3: =IF($K3="","",IF(O3="แจ้งย้าย",5,0)) | T3: =IF($K3="","",IF(O3<>"ตัดบัญชี",0,IF(S3="กทม.",IFERROR(INDEX(Fee_ตรวจรถ_กทม!$D:$D,MATCH(BB3,Fee_ตรวจรถ_กทม!$C:$C,0)),0),IF(S3="ต่างจังหวัด",IFERROR(INDEX(Fee_ตรวจรถ_ตจว!$D:$D,MATCH(L3&"|"&K3,Fee_ตรวจรถ_ตจว!$C:$C,0)),0),0)))) | U3: =IF($K3="","",IF(LEFT(K3,5)="รย.12","รถจักรยานยนต์","รถยนต์")) | V3: =IF($K3="","",IF(U3="รถยนต์",IF(N3="ใช่",INDEX(Fee_รถยนต์_Bill!$B:$B,MATCH("ค่าคำขอ (ขอใช้จังหวัดอื่น)",Fee_รถยนต์_Bill!$A:$A,0)),INDEX(Fee_รถยนต์_Bill!$B:$B,MATCH("ค่าคำขอ (ปกติ)",Fee_รถยนต์_Bill!$A:$A,0))),IF(N3="ใช่",INDEX(Fee_จยย_Bill!$B:$B,MATCH("ค่าคำขอ (ขอใช้จังหวัดอื่น)",Fee_จยย_Bill!$A:$A,0)),INDEX(Fee_จยย_Bill!$B:$B,MATCH("ค่าคำขอ (ปกติ)",Fee_จยย_Bill!$A:$A,0))))) | W3: =IF($K3="","",IF(N3="ใช่",IF(U3="รถยนต์",INDEX(Fee_รถยนต์_Bill!$B:$B,MATCH("ค่าธรรมเนียมอื่นๆ (ขอใช้จังหวัดอื่น)",Fee_รถยนต์_Bill!$A:$A,0)),INDEX(Fee_จยย_Bill!$B:$B,MATCH("ค่าธรรมเนียมอื่นๆ (ขอใช้จังหวัดอื่น)",Fee_จยย_Bill!$A:$A,0))),0)) | X3: =IF($K3="","",IF(U3="รถยนต์",INDEX(Fee_รถยนต์_Bill!$B:$B,MATCH("ค่าตรวจสภาพรถ (Step4)",Fee_รถยนต์_Bill!$A:$A,0)),INDEX(Fee_จยย_Bill!$B:$B,MATCH("ค่าตรวจสภาพรถ (จยย.)",Fee_จยย_Bill!$A:$A,0)))) | Y3: =IF($K3="","",IF(U3="รถยนต์",INDEX(Fee_รถยนต์_Bill!$B:$B,MATCH("ค่าแผ่นป้ายทะเบียนรถ",Fee_รถยนต์_Bill!$A:$A,0)),INDEX(Fee_จยย_Bill!$B:$B,MATCH("ค่าแผ่นป้ายทะเบียน",Fee_จยย_Bill!$A:$A,0)))) | Z3: =IF($K3="","",IF(U3="รถยนต์",INDEX(Fee_รถยนต์_Bill!$B:$B,MATCH("ค่าใบคู่มือการจดทะเบียน",Fee_รถยนต์_Bill!$A:$A,0)),INDEX(Fee_จยย_Bill!$B:$B,MATCH("ค่าใบคู่มือจดทะเบียน",Fee_จยย_Bill!$A:$A,0)))) | AC3: =IF($K3="","",IF(AB3="เลขประมูล",INDEX(Fee_รถยนต์_Bill!$B:$B,MATCH("ค่าขอใช้เลขทะเบียน - เลขประมูล",Fee_รถยนต์_Bill!$A:$A,0)),IF(AB3="ไม่ใช่เลขประมูล",INDEX(Fee_รถยนต์_Bill!$B:$B,MATCH("ค่าขอใช้เลขทะเบียน - ไม่ใช่เลขประมูล",Fee_รถยนต์_Bill!$A:$A,0)),0))) | AE3: =IF($K3="","",IF(AD3="ป้ายขาวดำ",INDEX(Fee_รถยนต์_Bill!$B:$B,MATCH("ค่าทำแผ่นป้ายทะเบียนใหม่ - ป้ายขาวดำ",Fee_รถยนต์_Bill!$A:$A,0)),IF(AD3="ป้ายประมูล",INDEX(Fee_รถยนต์_Bill!$B:$B,MATCH("ค่าทำแผ่นป้ายทะเบียนใหม่ - ป้ายประมูล",Fee_รถยนต์_Bill!$A:$A,0)),0))) | AG3: =IF($K3="","",IF(AF3="ใช่",INDEX(Fee_รถยนต์_Bill!$B:$B,MATCH("ค่าย้ายออกต่างจังหวัด",Fee_รถยนต์_Bill!$A:$A,0)),0)) | AH3: =IF($K3="","",SUM(V3:AG3)) | AJ3: =IF($K3="","",IF(U3="รถยนต์",IF(AI3="ใช่",INDEX(Fee_รถยนต์_NoBill!$B:$B,MATCH("ค่าอากร (ทำเพิ่มเติมเกิน 1 รายการ)",Fee_รถยนต์_NoBill!$A:$A,0)),INDEX(Fee_รถยนต์_NoBill!$B:$B,MATCH("ค่าอากร (ปกติ)",Fee_รถยนต์_NoBill!$A:$A,0))),IF(AI3="ใช่",INDEX(Fee_จยย_NoBill!$B:$B,MATCH("ค่าอากร (ทำเพิ่มเติมเกิน 1 รายการ)",Fee_จยย_NoBill!$A:$A,0)),INDEX(Fee_จยย_NoBill!$B:$B,MATCH("ค่าอากร (ปกติ)",Fee_จยย_NoBill!$A:$A,0))))) | AK3: =IF($K3="","",IF(U3="รถยนต์",IFERROR(INDEX(Fee_รถยนต์_NoBill!$B:$B,MATCH("ลงขัน - "&K3,Fee_รถยนต์_NoBill!$A:$A,0)),0),IFERROR(INDEX(Fee_จยย_NoBill!$B:$B,MATCH("ลงขัน - รย.12 ทุกประเภท (CC)",Fee_จยย_NoBill!$A:$A,0)),0))) | AM3: =IF($K3="","",IF(AL3="ใช่",IF(U3="รถยนต์",INDEX(Fee_รถยนต์_NoBill!$B:$B,MATCH("งานด่วนเพิ่ม (ต่อคัน)",Fee_รถยนต์_NoBill!$A:$A,0)),INDEX(Fee_จยย_NoBill!$B:$B,MATCH("ลงขันด่วนเพิ่ม (ต่อคัน)",Fee_จยย_NoBill!$A:$A,0))),0)) | AN3: =IF($K3="","",SUM(AJ3:AM3)) | AO3: =IF($K3="","",P3+Q3+R3+T3+AH3+AN3) | BA3: =IF($K3="","",IF(AND(K3="รย.1-เก๋ง 2 ตอน",OR(F3="Benz",F3="BMW",F3="Lexus",F3="Volvo")),F3,"อื่นๆ")) | BB3: =IF($K3="","",K3&"|"&BA3)
A4: =IF($K4="","",ROW()-1) | N4: =IF(OR(L4="",M4=""),"",IF(L4<>M4,"ใช่","ไม่ใช่")) | P4: =IF($K4="","",IF(O4="ตัดบัญชี",IFERROR(INDEX(Fee_ตัดบัญชี!$D:$D,MATCH(BB4,Fee_ตัดบัญชี!$C:$C,0)),0),0)) | Q4: =IF($K4="","",IF(O4="แจ้งย้าย",IFERROR(INDEX(Fee_แจ้งย้าย!$D:$D,MATCH(BB4,Fee_แจ้งย้าย!$C:$C,0)),0),0)) | R4: =IF($K4="","",IF(O4="แจ้งย้าย",5,0)) | T4: =IF($K4="","",IF(O4<>"ตัดบัญชี",0,IF(S4="กทม.",IFERROR(INDEX(Fee_ตรวจรถ_กทม!$D:$D,MATCH(BB4,Fee_ตรวจรถ_กทม!$C:$C,0)),0),IF(S4="ต่างจังหวัด",IFERROR(INDEX(Fee_ตรวจรถ_ตจว!$D:$D,MATCH(L4&"|"&K4,Fee_ตรวจรถ_ตจว!$C:$C,0)),0),0)))) | U4: =IF($K4="","",IF(LEFT(K4,5)="รย.12","รถจักรยานยนต์","รถยนต์")) | V4: =IF($K4="","",IF(U4="รถยนต์",IF(N4="ใช่",INDEX(Fee_รถยนต์_Bill!$B:$B,MATCH("ค่าคำขอ (ขอใช้จังหวัดอื่น)",Fee_รถยนต์_Bill!$A:$A,0)),INDEX(Fee_รถยนต์_Bill!$B:$B,MATCH("ค่าคำขอ (ปกติ)",Fee_รถยนต์_Bill!$A:$A,0))),IF(N4="ใช่",INDEX(Fee_จยย_Bill!$B:$B,MATCH("ค่าคำขอ (ขอใช้จังหวัดอื่น)",Fee_จยย_Bill!$A:$A,0)),INDEX(Fee_จยย_Bill!$B:$B,MATCH("ค่าคำขอ (ปกติ)",Fee_จยย_Bill!$A:$A,0))))) | W4: =IF($K4="","",IF(N4="ใช่",IF(U4="รถยนต์",INDEX(Fee_รถยนต์_Bill!$B:$B,MATCH("ค่าธรรมเนียมอื่นๆ (ขอใช้จังหวัดอื่น)",Fee_รถยนต์_Bill!$A:$A,0)),INDEX(Fee_จยย_Bill!$B:$B,MATCH("ค่าธรรมเนียมอื่นๆ (ขอใช้จังหวัดอื่น)",Fee_จยย_Bill!$A:$A,0))),0)) | X4: =IF($K4="","",IF(U4="รถยนต์",INDEX(Fee_รถยนต์_Bill!$B:$B,MATCH("ค่าตรวจสภาพรถ (Step4)",Fee_รถยนต์_Bill!$A:$A,0)),INDEX(Fee_จยย_Bill!$B:$B,MATCH("ค่าตรวจสภาพรถ (จยย.)",Fee_จยย_Bill!$A:$A,0)))) | Y4: =IF($K4="","",IF(U4="รถยนต์",INDEX(Fee_รถยนต์_Bill!$B:$B,MATCH("ค่าแผ่นป้ายทะเบียนรถ",Fee_รถยนต์_Bill!$A:$A,0)),INDEX(Fee_จยย_Bill!$B:$B,MATCH("ค่าแผ่นป้ายทะเบียน",Fee_จยย_Bill!$A:$A,0)))) | Z4: =IF($K4="","",IF(U4="รถยนต์",INDEX(Fee_รถยนต์_Bill!$B:$B,MATCH("ค่าใบคู่มือการจดทะเบียน",Fee_รถยนต์_Bill!$A:$A,0)),INDEX(Fee_จยย_Bill!$B:$B,MATCH("ค่าใบคู่มือจดทะเบียน",Fee_จยย_Bill!$A:$A,0)))) | AC4: =IF($K4="","",IF(AB4="เลขประมูล",INDEX(Fee_รถยนต์_Bill!$B:$B,MATCH("ค่าขอใช้เลขทะเบียน - เลขประมูล",Fee_รถยนต์_Bill!$A:$A,0)),IF(AB4="ไม่ใช่เลขประมูล",INDEX(Fee_รถยนต์_Bill!$B:$B,MATCH("ค่าขอใช้เลขทะเบียน - ไม่ใช่เลขประมูล",Fee_รถยนต์_Bill!$A:$A,0)),0))) | AE4: =IF($K4="","",IF(AD4="ป้ายขาวดำ",INDEX(Fee_รถยนต์_Bill!$B:$B,MATCH("ค่าทำแผ่นป้ายทะเบียนใหม่ - ป้ายขาวดำ",Fee_รถยนต์_Bill!$A:$A,0)),IF(AD4="ป้ายประมูล",INDEX(Fee_รถยนต์_Bill!$B:$B,MATCH("ค่าทำแผ่นป้ายทะเบียนใหม่ - ป้ายประมูล",Fee_รถยนต์_Bill!$A:$A,0)),0))) | AG4: =IF($K4="","",IF(AF4="ใช่",INDEX(Fee_รถยนต์_Bill!$B:$B,MATCH("ค่าย้ายออกต่างจังหวัด",Fee_รถยนต์_Bill!$A:$A,0)),0)) | AH4: =IF($K4="","",SUM(V4:AG4)) | AJ4: =IF($K4="","",IF(U4="รถยนต์",IF(AI4="ใช่",INDEX(Fee_รถยนต์_NoBill!$B:$B,MATCH("ค่าอากร (ทำเพิ่มเติมเกิน 1 รายการ)",Fee_รถยนต์_NoBill!$A:$A,0)),INDEX(Fee_รถยนต์_NoBill!$B:$B,MATCH("ค่าอากร (ปกติ)",Fee_รถยนต์_NoBill!$A:$A,0))),IF(AI4="ใช่",INDEX(Fee_จยย_NoBill!$B:$B,MATCH("ค่าอากร (ทำเพิ่มเติมเกิน 1 รายการ)",Fee_จยย_NoBill!$A:$A,0)),INDEX(Fee_จยย_NoBill!$B:$B,MATCH("ค่าอากร (ปกติ)",Fee_จยย_NoBill!$A:$A,0))))) | AK4: =IF($K4="","",IF(U4="รถยนต์",IFERROR(INDEX(Fee_รถยนต์_NoBill!$B:$B,MATCH("ลงขัน - "&K4,Fee_รถยนต์_NoBill!$A:$A,0)),0),IFERROR(INDEX(Fee_จยย_NoBill!$B:$B,MATCH("ลงขัน - รย.12 ทุกประเภท (CC)",Fee_จยย_NoBill!$A:$A,0)),0))) | AM4: =IF($K4="","",IF(AL4="ใช่",IF(U4="รถยนต์",INDEX(Fee_รถยนต์_NoBill!$B:$B,MATCH("งานด่วนเพิ่ม (ต่อคัน)",Fee_รถยนต์_NoBill!$A:$A,0)),INDEX(Fee_จยย_NoBill!$B:$B,MATCH("ลงขันด่วนเพิ่ม (ต่อคัน)",Fee_จยย_NoBill!$A:$A,0))),0)) | AN4: =IF($K4="","",SUM(AJ4:AM4)) | AO4: =IF($K4="","",P4+Q4+R4+T4+AH4+AN4) | BA4: =IF($K4="","",IF(AND(K4="รย.1-เก๋ง 2 ตอน",OR(F4="Benz",F4="BMW",F4="Lexus",F4="Volvo")),F4,"อื่นๆ")) | BB4: =IF($K4="","",K4&"|"&BA4)
A5: =IF($K5="","",ROW()-1) | N5: =IF(OR(L5="",M5=""),"",IF(L5<>M5,"ใช่","ไม่ใช่")) | P5: =IF($K5="","",IF(O5="ตัดบัญชี",IFERROR(INDEX(Fee_ตัดบัญชี!$D:$D,MATCH(BB5,Fee_ตัดบัญชี!$C:$C,0)),0),0)) | Q5: =IF($K5="","",IF(O5="แจ้งย้าย",IFERROR(INDEX(Fee_แจ้งย้าย!$D:$D,MATCH(BB5,Fee_แจ้งย้าย!$C:$C,0)),0),0)) | R5: =IF($K5="","",IF(O5="แจ้งย้าย",5,0)) | T5: =IF($K5="","",IF(O5<>"ตัดบัญชี",0,IF(S5="กทม.",IFERROR(INDEX(Fee_ตรวจรถ_กทม!$D:$D,MATCH(BB5,Fee_ตรวจรถ_กทม!$C:$C,0)),0),IF(S5="ต่างจังหวัด",IFERROR(INDEX(Fee_ตรวจรถ_ตจว!$D:$D,MATCH(L5&"|"&K5,Fee_ตรวจรถ_ตจว!$C:$C,0)),0),0)))) | U5: =IF($K5="","",IF(LEFT(K5,5)="รย.12","รถจักรยานยนต์","รถยนต์")) | V5: =IF($K5="","",IF(U5="รถยนต์",IF(N5="ใช่",INDEX(Fee_รถยนต์_Bill!$B:$B,MATCH("ค่าคำขอ (ขอใช้จังหวัดอื่น)",Fee_รถยนต์_Bill!$A:$A,0)),INDEX(Fee_รถยนต์_Bill!$B:$B,MATCH("ค่าคำขอ (ปกติ)",Fee_รถยนต์_Bill!$A:$A,0))),IF(N5="ใช่",INDEX(Fee_จยย_Bill!$B:$B,MATCH("ค่าคำขอ (ขอใช้จังหวัดอื่น)",Fee_จยย_Bill!$A:$A,0)),INDEX(Fee_จยย_Bill!$B:$B,MATCH("ค่าคำขอ (ปกติ)",Fee_จยย_Bill!$A:$A,0))))) | W5: =IF($K5="","",IF(N5="ใช่",IF(U5="รถยนต์",INDEX(Fee_รถยนต์_Bill!$B:$B,MATCH("ค่าธรรมเนียมอื่นๆ (ขอใช้จังหวัดอื่น)",Fee_รถยนต์_Bill!$A:$A,0)),INDEX(Fee_จยย_Bill!$B:$B,MATCH("ค่าธรรมเนียมอื่นๆ (ขอใช้จังหวัดอื่น)",Fee_จยย_Bill!$A:$A,0))),0)) | X5: =IF($K5="","",IF(U5="รถยนต์",INDEX(Fee_รถยนต์_Bill!$B:$B,MATCH("ค่าตรวจสภาพรถ (Step4)",Fee_รถยนต์_Bill!$A:$A,0)),INDEX(Fee_จยย_Bill!$B:$B,MATCH("ค่าตรวจสภาพรถ (จยย.)",Fee_จยย_Bill!$A:$A,0)))) | Y5: =IF($K5="","",IF(U5="รถยนต์",INDEX(Fee_รถยนต์_Bill!$B:$B,MATCH("ค่าแผ่นป้ายทะเบียนรถ",Fee_รถยนต์_Bill!$A:$A,0)),INDEX(Fee_จยย_Bill!$B:$B,MATCH("ค่าแผ่นป้ายทะเบียน",Fee_จยย_Bill!$A:$A,0)))) | Z5: =IF($K5="","",IF(U5="รถยนต์",INDEX(Fee_รถยนต์_Bill!$B:$B,MATCH("ค่าใบคู่มือการจดทะเบียน",Fee_รถยนต์_Bill!$A:$A,0)),INDEX(Fee_จยย_Bill!$B:$B,MATCH("ค่าใบคู่มือจดทะเบียน",Fee_จยย_Bill!$A:$A,0)))) | AC5: =IF($K5="","",IF(AB5="เลขประมูล",INDEX(Fee_รถยนต์_Bill!$B:$B,MATCH("ค่าขอใช้เลขทะเบียน - เลขประมูล",Fee_รถยนต์_Bill!$A:$A,0)),IF(AB5="ไม่ใช่เลขประมูล",INDEX(Fee_รถยนต์_Bill!$B:$B,MATCH("ค่าขอใช้เลขทะเบียน - ไม่ใช่เลขประมูล",Fee_รถยนต์_Bill!$A:$A,0)),0))) | AE5: =IF($K5="","",IF(AD5="ป้ายขาวดำ",INDEX(Fee_รถยนต์_Bill!$B:$B,MATCH("ค่าทำแผ่นป้ายทะเบียนใหม่ - ป้ายขาวดำ",Fee_รถยนต์_Bill!$A:$A,0)),IF(AD5="ป้ายประมูล",INDEX(Fee_รถยนต์_Bill!$B:$B,MATCH("ค่าทำแผ่นป้ายทะเบียนใหม่ - ป้ายประมูล",Fee_รถยนต์_Bill!$A:$A,0)),0))) | AG5: =IF($K5="","",IF(AF5="ใช่",INDEX(Fee_รถยนต์_Bill!$B:$B,MATCH("ค่าย้ายออกต่างจังหวัด",Fee_รถยนต์_Bill!$A:$A,0)),0)) | AH5: =IF($K5="","",SUM(V5:AG5)) | AJ5: =IF($K5="","",IF(U5="รถยนต์",IF(AI5="ใช่",INDEX(Fee_รถยนต์_NoBill!$B:$B,MATCH("ค่าอากร (ทำเพิ่มเติมเกิน 1 รายการ)",Fee_รถยนต์_NoBill!$A:$A,0)),INDEX(Fee_รถยนต์_NoBill!$B:$B,MATCH("ค่าอากร (ปกติ)",Fee_รถยนต์_NoBill!$A:$A,0))),IF(AI5="ใช่",INDEX(Fee_จยย_NoBill!$B:$B,MATCH("ค่าอากร (ทำเพิ่มเติมเกิน 1 รายการ)",Fee_จยย_NoBill!$A:$A,0)),INDEX(Fee_จยย_NoBill!$B:$B,MATCH("ค่าอากร (ปกติ)",Fee_จยย_NoBill!$A:$A,0))))) | AK5: =IF($K5="","",IF(U5="รถยนต์",IFERROR(INDEX(Fee_รถยนต์_NoBill!$B:$B,MATCH("ลงขัน - "&K5,Fee_รถยนต์_NoBill!$A:$A,0)),0),IFERROR(INDEX(Fee_จยย_NoBill!$B:$B,MATCH("ลงขัน - รย.12 ทุกประเภท (CC)",Fee_จยย_NoBill!$A:$A,0)),0))) | AM5: =IF($K5="","",IF(AL5="ใช่",IF(U5="รถยนต์",INDEX(Fee_รถยนต์_NoBill!$B:$B,MATCH("งานด่วนเพิ่ม (ต่อคัน)",Fee_รถยนต์_NoBill!$A:$A,0)),INDEX(Fee_จยย_NoBill!$B:$B,MATCH("ลงขันด่วนเพิ่ม (ต่อคัน)",Fee_จยย_NoBill!$A:$A,0))),0)) | AN5: =IF($K5="","",SUM(AJ5:AM5)) | AO5: =IF($K5="","",P5+Q5+R5+T5+AH5+AN5) | BA5: =IF($K5="","",IF(AND(K5="รย.1-เก๋ง 2 ตอน",OR(F5="Benz",F5="BMW",F5="Lexus",F5="Volvo")),F5,"อื่นๆ")) | BB5: =IF($K5="","",K5&"|"&BA5)
A6: =IF($K6="","",ROW()-1) | N6: =IF(OR(L6="",M6=""),"",IF(L6<>M6,"ใช่","ไม่ใช่")) | P6: =IF($K6="","",IF(O6="ตัดบัญชี",IFERROR(INDEX(Fee_ตัดบัญชี!$D:$D,MATCH(BB6,Fee_ตัดบัญชี!$C:$C,0)),0),0)) | Q6: =IF($K6="","",IF(O6="แจ้งย้าย",IFERROR(INDEX(Fee_แจ้งย้าย!$D:$D,MATCH(BB6,Fee_แจ้งย้าย!$C:$C,0)),0),0)) | R6: =IF($K6="","",IF(O6="แจ้งย้าย",5,0)) | T6: =IF($K6="","",IF(O6<>"ตัดบัญชี",0,IF(S6="กทม.",IFERROR(INDEX(Fee_ตรวจรถ_กทม!$D:$D,MATCH(BB6,Fee_ตรวจรถ_กทม!$C:$C,0)),0),IF(S6="ต่างจังหวัด",IFERROR(INDEX(Fee_ตรวจรถ_ตจว!$D:$D,MATCH(L6&"|"&K6,Fee_ตรวจรถ_ตจว!$C:$C,0)),0),0)))) | U6: =IF($K6="","",IF(LEFT(K6,5)="รย.12","รถจักรยานยนต์","รถยนต์")) | V6: =IF($K6="","",IF(U6="รถยนต์",IF(N6="ใช่",INDEX(Fee_รถยนต์_Bill!$B:$B,MATCH("ค่าคำขอ (ขอใช้จังหวัดอื่น)",Fee_รถยนต์_Bill!$A:$A,0)),INDEX(Fee_รถยนต์_Bill!$B:$B,MATCH("ค่าคำขอ (ปกติ)",Fee_รถยนต์_Bill!$A:$A,0))),IF(N6="ใช่",INDEX(Fee_จยย_Bill!$B:$B,MATCH("ค่าคำขอ (ขอใช้จังหวัดอื่น)",Fee_จยย_Bill!$A:$A,0)),INDEX(Fee_จยย_Bill!$B:$B,MATCH("ค่าคำขอ (ปกติ)",Fee_จยย_Bill!$A:$A,0))))) | W6: =IF($K6="","",IF(N6="ใช่",IF(U6="รถยนต์",INDEX(Fee_รถยนต์_Bill!$B:$B,MATCH("ค่าธรรมเนียมอื่นๆ (ขอใช้จังหวัดอื่น)",Fee_รถยนต์_Bill!$A:$A,0)),INDEX(Fee_จยย_Bill!$B:$B,MATCH("ค่าธรรมเนียมอื่นๆ (ขอใช้จังหวัดอื่น)",Fee_จยย_Bill!$A:$A,0))),0)) | X6: =IF($K6="","",IF(U6="รถยนต์",INDEX(Fee_รถยนต์_Bill!$B:$B,MATCH("ค่าตรวจสภาพรถ (Step4)",Fee_รถยนต์_Bill!$A:$A,0)),INDEX(Fee_จยย_Bill!$B:$B,MATCH("ค่าตรวจสภาพรถ (จยย.)",Fee_จยย_Bill!$A:$A,0)))) | Y6: =IF($K6="","",IF(U6="รถยนต์",INDEX(Fee_รถยนต์_Bill!$B:$B,MATCH("ค่าแผ่นป้ายทะเบียนรถ",Fee_รถยนต์_Bill!$A:$A,0)),INDEX(Fee_จยย_Bill!$B:$B,MATCH("ค่าแผ่นป้ายทะเบียน",Fee_จยย_Bill!$A:$A,0)))) | Z6: =IF($K6="","",IF(U6="รถยนต์",INDEX(Fee_รถยนต์_Bill!$B:$B,MATCH("ค่าใบคู่มือการจดทะเบียน",Fee_รถยนต์_Bill!$A:$A,0)),INDEX(Fee_จยย_Bill!$B:$B,MATCH("ค่าใบคู่มือจดทะเบียน",Fee_จยย_Bill!$A:$A,0)))) | AC6: =IF($K6="","",IF(AB6="เลขประมูล",INDEX(Fee_รถยนต์_Bill!$B:$B,MATCH("ค่าขอใช้เลขทะเบียน - เลขประมูล",Fee_รถยนต์_Bill!$A:$A,0)),IF(AB6="ไม่ใช่เลขประมูล",INDEX(Fee_รถยนต์_Bill!$B:$B,MATCH("ค่าขอใช้เลขทะเบียน - ไม่ใช่เลขประมูล",Fee_รถยนต์_Bill!$A:$A,0)),0))) | AE6: =IF($K6="","",IF(AD6="ป้ายขาวดำ",INDEX(Fee_รถยนต์_Bill!$B:$B,MATCH("ค่าทำแผ่นป้ายทะเบียนใหม่ - ป้ายขาวดำ",Fee_รถยนต์_Bill!$A:$A,0)),IF(AD6="ป้ายประมูล",INDEX(Fee_รถยนต์_Bill!$B:$B,MATCH("ค่าทำแผ่นป้ายทะเบียนใหม่ - ป้ายประมูล",Fee_รถยนต์_Bill!$A:$A,0)),0))) | AG6: =IF($K6="","",IF(AF6="ใช่",INDEX(Fee_รถยนต์_Bill!$B:$B,MATCH("ค่าย้ายออกต่างจังหวัด",Fee_รถยนต์_Bill!$A:$A,0)),0)) | AH6: =IF($K6="","",SUM(V6:AG6)) | AJ6: =IF($K6="","",IF(U6="รถยนต์",IF(AI6="ใช่",INDEX(Fee_รถยนต์_NoBill!$B:$B,MATCH("ค่าอากร (ทำเพิ่มเติมเกิน 1 รายการ)",Fee_รถยนต์_NoBill!$A:$A,0)),INDEX(Fee_รถยนต์_NoBill!$B:$B,MATCH("ค่าอากร (ปกติ)",Fee_รถยนต์_NoBill!$A:$A,0))),IF(AI6="ใช่",INDEX(Fee_จยย_NoBill!$B:$B,MATCH("ค่าอากร (ทำเพิ่มเติมเกิน 1 รายการ)",Fee_จยย_NoBill!$A:$A,0)),INDEX(Fee_จยย_NoBill!$B:$B,MATCH("ค่าอากร (ปกติ)",Fee_จยย_NoBill!$A:$A,0))))) | AK6: =IF($K6="","",IF(U6="รถยนต์",IFERROR(INDEX(Fee_รถยนต์_NoBill!$B:$B,MATCH("ลงขัน - "&K6,Fee_รถยนต์_NoBill!$A:$A,0)),0),IFERROR(INDEX(Fee_จยย_NoBill!$B:$B,MATCH("ลงขัน - รย.12 ทุกประเภท (CC)",Fee_จยย_NoBill!$A:$A,0)),0))) | AM6: =IF($K6="","",IF(AL6="ใช่",IF(U6="รถยนต์",INDEX(Fee_รถยนต์_NoBill!$B:$B,MATCH("งานด่วนเพิ่ม (ต่อคัน)",Fee_รถยนต์_NoBill!$A:$A,0)),INDEX(Fee_จยย_NoBill!$B:$B,MATCH("ลงขันด่วนเพิ่ม (ต่อคัน)",Fee_จยย_NoBill!$A:$A,0))),0)) | AN6: =IF($K6="","",SUM(AJ6:AM6)) | AO6: =IF($K6="","",P6+Q6+R6+T6+AH6+AN6) | BA6: =IF($K6="","",IF(AND(K6="รย.1-เก๋ง 2 ตอน",OR(F6="Benz",F6="BMW",F6="Lexus",F6="Volvo")),F6,"อื่นๆ")) | BB6: =IF($K6="","",K6&"|"&BA6)
A7: =IF($K7="","",ROW()-1) | N7: =IF(OR(L7="",M7=""),"",IF(L7<>M7,"ใช่","ไม่ใช่")) | P7: =IF($K7="","",IF(O7="ตัดบัญชี",IFERROR(INDEX(Fee_ตัดบัญชี!$D:$D,MATCH(BB7,Fee_ตัดบัญชี!$C:$C,0)),0),0)) | Q7: =IF($K7="","",IF(O7="แจ้งย้าย",IFERROR(INDEX(Fee_แจ้งย้าย!$D:$D,MATCH(BB7,Fee_แจ้งย้าย!$C:$C,0)),0),0)) | R7: =IF($K7="","",IF(O7="แจ้งย้าย",5,0)) | T7: =IF($K7="","",IF(O7<>"ตัดบัญชี",0,IF(S7="กทม.",IFERROR(INDEX(Fee_ตรวจรถ_กทม!$D:$D,MATCH(BB7,Fee_ตรวจรถ_กทม!$C:$C,0)),0),IF(S7="ต่างจังหวัด",IFERROR(INDEX(Fee_ตรวจรถ_ตจว!$D:$D,MATCH(L7&"|"&K7,Fee_ตรวจรถ_ตจว!$C:$C,0)),0),0)))) | U7: =IF($K7="","",IF(LEFT(K7,5)="รย.12","รถจักรยานยนต์","รถยนต์")) | V7: =IF($K7="","",IF(U7="รถยนต์",IF(N7="ใช่",INDEX(Fee_รถยนต์_Bill!$B:$B,MATCH("ค่าคำขอ (ขอใช้จังหวัดอื่น)",Fee_รถยนต์_Bill!$A:$A,0)),INDEX(Fee_รถยนต์_Bill!$B:$B,MATCH("ค่าคำขอ (ปกติ)",Fee_รถยนต์_Bill!$A:$A,0))),IF(N7="ใช่",INDEX(Fee_จยย_Bill!$B:$B,MATCH("ค่าคำขอ (ขอใช้จังหวัดอื่น)",Fee_จยย_Bill!$A:$A,0)),INDEX(Fee_จยย_Bill!$B:$B,MATCH("ค่าคำขอ (ปกติ)",Fee_จยย_Bill!$A:$A,0))))) | W7: =IF($K7="","",IF(N7="ใช่",IF(U7="รถยนต์",INDEX(Fee_รถยนต์_Bill!$B:$B,MATCH("ค่าธรรมเนียมอื่นๆ (ขอใช้จังหวัดอื่น)",Fee_รถยนต์_Bill!$A:$A,0)),INDEX(Fee_จยย_Bill!$B:$B,MATCH("ค่าธรรมเนียมอื่นๆ (ขอใช้จังหวัดอื่น)",Fee_จยย_Bill!$A:$A,0))),0)) | X7: =IF($K7="","",IF(U7="รถยนต์",INDEX(Fee_รถยนต์_Bill!$B:$B,MATCH("ค่าตรวจสภาพรถ (Step4)",Fee_รถยนต์_Bill!$A:$A,0)),INDEX(Fee_จยย_Bill!$B:$B,MATCH("ค่าตรวจสภาพรถ (จยย.)",Fee_จยย_Bill!$A:$A,0)))) | Y7: =IF($K7="","",IF(U7="รถยนต์",INDEX(Fee_รถยนต์_Bill!$B:$B,MATCH("ค่าแผ่นป้ายทะเบียนรถ",Fee_รถยนต์_Bill!$A:$A,0)),INDEX(Fee_จยย_Bill!$B:$B,MATCH("ค่าแผ่นป้ายทะเบียน",Fee_จยย_Bill!$A:$A,0)))) | Z7: =IF($K7="","",IF(U7="รถยนต์",INDEX(Fee_รถยนต์_Bill!$B:$B,MATCH("ค่าใบคู่มือการจดทะเบียน",Fee_รถยนต์_Bill!$A:$A,0)),INDEX(Fee_จยย_Bill!$B:$B,MATCH("ค่าใบคู่มือจดทะเบียน",Fee_จยย_Bill!$A:$A,0)))) | AC7: =IF($K7="","",IF(AB7="เลขประมูล",INDEX(Fee_รถยนต์_Bill!$B:$B,MATCH("ค่าขอใช้เลขทะเบียน - เลขประมูล",Fee_รถยนต์_Bill!$A:$A,0)),IF(AB7="ไม่ใช่เลขประมูล",INDEX(Fee_รถยนต์_Bill!$B:$B,MATCH("ค่าขอใช้เลขทะเบียน - ไม่ใช่เลขประมูล",Fee_รถยนต์_Bill!$A:$A,0)),0))) | AE7: =IF($K7="","",IF(AD7="ป้ายขาวดำ",INDEX(Fee_รถยนต์_Bill!$B:$B,MATCH("ค่าทำแผ่นป้ายทะเบียนใหม่ - ป้ายขาวดำ",Fee_รถยนต์_Bill!$A:$A,0)),IF(AD7="ป้ายประมูล",INDEX(Fee_รถยนต์_Bill!$B:$B,MATCH("ค่าทำแผ่นป้ายทะเบียนใหม่ - ป้ายประมูล",Fee_รถยนต์_Bill!$A:$A,0)),0))) | AG7: =IF($K7="","",IF(AF7="ใช่",INDEX(Fee_รถยนต์_Bill!$B:$B,MATCH("ค่าย้ายออกต่างจังหวัด",Fee_รถยนต์_Bill!$A:$A,0)),0)) | AH7: =IF($K7="","",SUM(V7:AG7)) | AJ7: =IF($K7="","",IF(U7="รถยนต์",IF(AI7="ใช่",INDEX(Fee_รถยนต์_NoBill!$B:$B,MATCH("ค่าอากร (ทำเพิ่มเติมเกิน 1 รายการ)",Fee_รถยนต์_NoBill!$A:$A,0)),INDEX(Fee_รถยนต์_NoBill!$B:$B,MATCH("ค่าอากร (ปกติ)",Fee_รถยนต์_NoBill!$A:$A,0))),IF(AI7="ใช่",INDEX(Fee_จยย_NoBill!$B:$B,MATCH("ค่าอากร (ทำเพิ่มเติมเกิน 1 รายการ)",Fee_จยย_NoBill!$A:$A,0)),INDEX(Fee_จยย_NoBill!$B:$B,MATCH("ค่าอากร (ปกติ)",Fee_จยย_NoBill!$A:$A,0))))) | AK7: =IF($K7="","",IF(U7="รถยนต์",IFERROR(INDEX(Fee_รถยนต์_NoBill!$B:$B,MATCH("ลงขัน - "&K7,Fee_รถยนต์_NoBill!$A:$A,0)),0),IFERROR(INDEX(Fee_จยย_NoBill!$B:$B,MATCH("ลงขัน - รย.12 ทุกประเภท (CC)",Fee_จยย_NoBill!$A:$A,0)),0))) | AM7: =IF($K7="","",IF(AL7="ใช่",IF(U7="รถยนต์",INDEX(Fee_รถยนต์_NoBill!$B:$B,MATCH("งานด่วนเพิ่ม (ต่อคัน)",Fee_รถยนต์_NoBill!$A:$A,0)),INDEX(Fee_จยย_NoBill!$B:$B,MATCH("ลงขันด่วนเพิ่ม (ต่อคัน)",Fee_จยย_NoBill!$A:$A,0))),0)) | AN7: =IF($K7="","",SUM(AJ7:AM7)) | AO7: =IF($K7="","",P7+Q7+R7+T7+AH7+AN7) | BA7: =IF($K7="","",IF(AND(K7="รย.1-เก๋ง 2 ตอน",OR(F7="Benz",F7="BMW",F7="Lexus",F7="Volvo")),F7,"อื่นๆ")) | BB7: =IF($K7="","",K7&"|"&BA7)
A8: =IF($K8="","",ROW()-1) | N8: =IF(OR(L8="",M8=""),"",IF(L8<>M8,"ใช่","ไม่ใช่")) | P8: =IF($K8="","",IF(O8="ตัดบัญชี",IFERROR(INDEX(Fee_ตัดบัญชี!$D:$D,MATCH(BB8,Fee_ตัดบัญชี!$C:$C,0)),0),0)) | Q8: =IF($K8="","",IF(O8="แจ้งย้าย",IFERROR(INDEX(Fee_แจ้งย้าย!$D:$D,MATCH(BB8,Fee_แจ้งย้าย!$C:$C,0)),0),0)) | R8: =IF($K8="","",IF(O8="แจ้งย้าย",5,0)) | T8: =IF($K8="","",IF(O8<>"ตัดบัญชี",0,IF(S8="กทม.",IFERROR(INDEX(Fee_ตรวจรถ_กทม!$D:$D,MATCH(BB8,Fee_ตรวจรถ_กทม!$C:$C,0)),0),IF(S8="ต่างจังหวัด",IFERROR(INDEX(Fee_ตรวจรถ_ตจว!$D:$D,MATCH(L8&"|"&K8,Fee_ตรวจรถ_ตจว!$C:$C,0)),0),0)))) | U8: =IF($K8="","",IF(LEFT(K8,5)="รย.12","รถจักรยานยนต์","รถยนต์")) | V8: =IF($K8="","",IF(U8="รถยนต์",IF(N8="ใช่",INDEX(Fee_รถยนต์_Bill!$B:$B,MATCH("ค่าคำขอ (ขอใช้จังหวัดอื่น)",Fee_รถยนต์_Bill!$A:$A,0)),INDEX(Fee_รถยนต์_Bill!$B:$B,MATCH("ค่าคำขอ (ปกติ)",Fee_รถยนต์_Bill!$A:$A,0))),IF(N8="ใช่",INDEX(Fee_จยย_Bill!$B:$B,MATCH("ค่าคำขอ (ขอใช้จังหวัดอื่น)",Fee_จยย_Bill!$A:$A,0)),INDEX(Fee_จยย_Bill!$B:$B,MATCH("ค่าคำขอ (ปกติ)",Fee_จยย_Bill!$A:$A,0))))) | W8: =IF($K8="","",IF(N8="ใช่",IF(U8="รถยนต์",INDEX(Fee_รถยนต์_Bill!$B:$B,MATCH("ค่าธรรมเนียมอื่นๆ (ขอใช้จังหวัดอื่น)",Fee_รถยนต์_Bill!$A:$A,0)),INDEX(Fee_จยย_Bill!$B:$B,MATCH("ค่าธรรมเนียมอื่นๆ (ขอใช้จังหวัดอื่น)",Fee_จยย_Bill!$A:$A,0))),0)) | X8: =IF($K8="","",IF(U8="รถยนต์",INDEX(Fee_รถยนต์_Bill!$B:$B,MATCH("ค่าตรวจสภาพรถ (Step4)",Fee_รถยนต์_Bill!$A:$A,0)),INDEX(Fee_จยย_Bill!$B:$B,MATCH("ค่าตรวจสภาพรถ (จยย.)",Fee_จยย_Bill!$A:$A,0)))) | Y8: =IF($K8="","",IF(U8="รถยนต์",INDEX(Fee_รถยนต์_Bill!$B:$B,MATCH("ค่าแผ่นป้ายทะเบียนรถ",Fee_รถยนต์_Bill!$A:$A,0)),INDEX(Fee_จยย_Bill!$B:$B,MATCH("ค่าแผ่นป้ายทะเบียน",Fee_จยย_Bill!$A:$A,0)))) | Z8: =IF($K8="","",IF(U8="รถยนต์",INDEX(Fee_รถยนต์_Bill!$B:$B,MATCH("ค่าใบคู่มือการจดทะเบียน",Fee_รถยนต์_Bill!$A:$A,0)),INDEX(Fee_จยย_Bill!$B:$B,MATCH("ค่าใบคู่มือจดทะเบียน",Fee_จยย_Bill!$A:$A,0)))) | AC8: =IF($K8="","",IF(AB8="เลขประมูล",INDEX(Fee_รถยนต์_Bill!$B:$B,MATCH("ค่าขอใช้เลขทะเบียน - เลขประมูล",Fee_รถยนต์_Bill!$A:$A,0)),IF(AB8="ไม่ใช่เลขประมูล",INDEX(Fee_รถยนต์_Bill!$B:$B,MATCH("ค่าขอใช้เลขทะเบียน - ไม่ใช่เลขประมูล",Fee_รถยนต์_Bill!$A:$A,0)),0))) | AE8: =IF($K8="","",IF(AD8="ป้ายขาวดำ",INDEX(Fee_รถยนต์_Bill!$B:$B,MATCH("ค่าทำแผ่นป้ายทะเบียนใหม่ - ป้ายขาวดำ",Fee_รถยนต์_Bill!$A:$A,0)),IF(AD8="ป้ายประมูล",INDEX(Fee_รถยนต์_Bill!$B:$B,MATCH("ค่าทำแผ่นป้ายทะเบียนใหม่ - ป้ายประมูล",Fee_รถยนต์_Bill!$A:$A,0)),0))) | AG8: =IF($K8="","",IF(AF8="ใช่",INDEX(Fee_รถยนต์_Bill!$B:$B,MATCH("ค่าย้ายออกต่างจังหวัด",Fee_รถยนต์_Bill!$A:$A,0)),0)) | AH8: =IF($K8="","",SUM(V8:AG8)) | AJ8: =IF($K8="","",IF(U8="รถยนต์",IF(AI8="ใช่",INDEX(Fee_รถยนต์_NoBill!$B:$B,MATCH("ค่าอากร (ทำเพิ่มเติมเกิน 1 รายการ)",Fee_รถยนต์_NoBill!$A:$A,0)),INDEX(Fee_รถยนต์_NoBill!$B:$B,MATCH("ค่าอากร (ปกติ)",Fee_รถยนต์_NoBill!$A:$A,0))),IF(AI8="ใช่",INDEX(Fee_จยย_NoBill!$B:$B,MATCH("ค่าอากร (ทำเพิ่มเติมเกิน 1 รายการ)",Fee_จยย_NoBill!$A:$A,0)),INDEX(Fee_จยย_NoBill!$B:$B,MATCH("ค่าอากร (ปกติ)",Fee_จยย_NoBill!$A:$A,0))))) | AK8: =IF($K8="","",IF(U8="รถยนต์",IFERROR(INDEX(Fee_รถยนต์_NoBill!$B:$B,MATCH("ลงขัน - "&K8,Fee_รถยนต์_NoBill!$A:$A,0)),0),IFERROR(INDEX(Fee_จยย_NoBill!$B:$B,MATCH("ลงขัน - รย.12 ทุกประเภท (CC)",Fee_จยย_NoBill!$A:$A,0)),0))) | AM8: =IF($K8="","",IF(AL8="ใช่",IF(U8="รถยนต์",INDEX(Fee_รถยนต์_NoBill!$B:$B,MATCH("งานด่วนเพิ่ม (ต่อคัน)",Fee_รถยนต์_NoBill!$A:$A,0)),INDEX(Fee_จยย_NoBill!$B:$B,MATCH("ลงขันด่วนเพิ่ม (ต่อคัน)",Fee_จยย_NoBill!$A:$A,0))),0)) | AN8: =IF($K8="","",SUM(AJ8:AM8)) | AO8: =IF($K8="","",P8+Q8+R8+T8+AH8+AN8) | BA8: =IF($K8="","",IF(AND(K8="รย.1-เก๋ง 2 ตอน",OR(F8="Benz",F8="BMW",F8="Lexus",F8="Volvo")),F8,"อื่นๆ")) | BB8: =IF($K8="","",K8&"|"&BA8)
A9: =IF($K9="","",ROW()-1) | N9: =IF(OR(L9="",M9=""),"",IF(L9<>M9,"ใช่","ไม่ใช่")) | P9: =IF($K9="","",IF(O9="ตัดบัญชี",IFERROR(INDEX(Fee_ตัดบัญชี!$D:$D,MATCH(BB9,Fee_ตัดบัญชี!$C:$C,0)),0),0)) | Q9: =IF($K9="","",IF(O9="แจ้งย้าย",IFERROR(INDEX(Fee_แจ้งย้าย!$D:$D,MATCH(BB9,Fee_แจ้งย้าย!$C:$C,0)),0),0)) | R9: =IF($K9="","",IF(O9="แจ้งย้าย",5,0)) | T9: =IF($K9="","",IF(O9<>"ตัดบัญชี",0,IF(S9="กทม.",IFERROR(INDEX(Fee_ตรวจรถ_กทม!$D:$D,MATCH(BB9,Fee_ตรวจรถ_กทม!$C:$C,0)),0),IF(S9="ต่างจังหวัด",IFERROR(INDEX(Fee_ตรวจรถ_ตจว!$D:$D,MATCH(L9&"|"&K9,Fee_ตรวจรถ_ตจว!$C:$C,0)),0),0)))) | U9: =IF($K9="","",IF(LEFT(K9,5)="รย.12","รถจักรยานยนต์","รถยนต์")) | V9: =IF($K9="","",IF(U9="รถยนต์",IF(N9="ใช่",INDEX(Fee_รถยนต์_Bill!$B:$B,MATCH("ค่าคำขอ (ขอใช้จังหวัดอื่น)",Fee_รถยนต์_Bill!$A:$A,0)),INDEX(Fee_รถยนต์_Bill!$B:$B,MATCH("ค่าคำขอ (ปกติ)",Fee_รถยนต์_Bill!$A:$A,0))),IF(N9="ใช่",INDEX(Fee_จยย_Bill!$B:$B,MATCH("ค่าคำขอ (ขอใช้จังหวัดอื่น)",Fee_จยย_Bill!$A:$A,0)),INDEX(Fee_จยย_Bill!$B:$B,MATCH("ค่าคำขอ (ปกติ)",Fee_จยย_Bill!$A:$A,0))))) | W9: =IF($K9="","",IF(N9="ใช่",IF(U9="รถยนต์",INDEX(Fee_รถยนต์_Bill!$B:$B,MATCH("ค่าธรรมเนียมอื่นๆ (ขอใช้จังหวัดอื่น)",Fee_รถยนต์_Bill!$A:$A,0)),INDEX(Fee_จยย_Bill!$B:$B,MATCH("ค่าธรรมเนียมอื่นๆ (ขอใช้จังหวัดอื่น)",Fee_จยย_Bill!$A:$A,0))),0)) | X9: =IF($K9="","",IF(U9="รถยนต์",INDEX(Fee_รถยนต์_Bill!$B:$B,MATCH("ค่าตรวจสภาพรถ (Step4)",Fee_รถยนต์_Bill!$A:$A,0)),INDEX(Fee_จยย_Bill!$B:$B,MATCH("ค่าตรวจสภาพรถ (จยย.)",Fee_จยย_Bill!$A:$A,0)))) | Y9: =IF($K9="","",IF(U9="รถยนต์",INDEX(Fee_รถยนต์_Bill!$B:$B,MATCH("ค่าแผ่นป้ายทะเบียนรถ",Fee_รถยนต์_Bill!$A:$A,0)),INDEX(Fee_จยย_Bill!$B:$B,MATCH("ค่าแผ่นป้ายทะเบียน",Fee_จยย_Bill!$A:$A,0)))) | Z9: =IF($K9="","",IF(U9="รถยนต์",INDEX(Fee_รถยนต์_Bill!$B:$B,MATCH("ค่าใบคู่มือการจดทะเบียน",Fee_รถยนต์_Bill!$A:$A,0)),INDEX(Fee_จยย_Bill!$B:$B,MATCH("ค่าใบคู่มือจดทะเบียน",Fee_จยย_Bill!$A:$A,0)))) | AC9: =IF($K9="","",IF(AB9="เลขประมูล",INDEX(Fee_รถยนต์_Bill!$B:$B,MATCH("ค่าขอใช้เลขทะเบียน - เลขประมูล",Fee_รถยนต์_Bill!$A:$A,0)),IF(AB9="ไม่ใช่เลขประมูล",INDEX(Fee_รถยนต์_Bill!$B:$B,MATCH("ค่าขอใช้เลขทะเบียน - ไม่ใช่เลขประมูล",Fee_รถยนต์_Bill!$A:$A,0)),0))) | AE9: =IF($K9="","",IF(AD9="ป้ายขาวดำ",INDEX(Fee_รถยนต์_Bill!$B:$B,MATCH("ค่าทำแผ่นป้ายทะเบียนใหม่ - ป้ายขาวดำ",Fee_รถยนต์_Bill!$A:$A,0)),IF(AD9="ป้ายประมูล",INDEX(Fee_รถยนต์_Bill!$B:$B,MATCH("ค่าทำแผ่นป้ายทะเบียนใหม่ - ป้ายประมูล",Fee_รถยนต์_Bill!$A:$A,0)),0))) | AG9: =IF($K9="","",IF(AF9="ใช่",INDEX(Fee_รถยนต์_Bill!$B:$B,MATCH("ค่าย้ายออกต่างจังหวัด",Fee_รถยนต์_Bill!$A:$A,0)),0)) | AH9: =IF($K9="","",SUM(V9:AG9)) | AJ9: =IF($K9="","",IF(U9="รถยนต์",IF(AI9="ใช่",INDEX(Fee_รถยนต์_NoBill!$B:$B,MATCH("ค่าอากร (ทำเพิ่มเติมเกิน 1 รายการ)",Fee_รถยนต์_NoBill!$A:$A,0)),INDEX(Fee_รถยนต์_NoBill!$B:$B,MATCH("ค่าอากร (ปกติ)",Fee_รถยนต์_NoBill!$A:$A,0))),IF(AI9="ใช่",INDEX(Fee_จยย_NoBill!$B:$B,MATCH("ค่าอากร (ทำเพิ่มเติมเกิน 1 รายการ)",Fee_จยย_NoBill!$A:$A,0)),INDEX(Fee_จยย_NoBill!$B:$B,MATCH("ค่าอากร (ปกติ)",Fee_จยย_NoBill!$A:$A,0))))) | AK9: =IF($K9="","",IF(U9="รถยนต์",IFERROR(INDEX(Fee_รถยนต์_NoBill!$B:$B,MATCH("ลงขัน - "&K9,Fee_รถยนต์_NoBill!$A:$A,0)),0),IFERROR(INDEX(Fee_จยย_NoBill!$B:$B,MATCH("ลงขัน - รย.12 ทุกประเภท (CC)",Fee_จยย_NoBill!$A:$A,0)),0))) | AM9: =IF($K9="","",IF(AL9="ใช่",IF(U9="รถยนต์",INDEX(Fee_รถยนต์_NoBill!$B:$B,MATCH("งานด่วนเพิ่ม (ต่อคัน)",Fee_รถยนต์_NoBill!$A:$A,0)),INDEX(Fee_จยย_NoBill!$B:$B,MATCH("ลงขันด่วนเพิ่ม (ต่อคัน)",Fee_จยย_NoBill!$A:$A,0))),0)) | AN9: =IF($K9="","",SUM(AJ9:AM9)) | AO9: =IF($K9="","",P9+Q9+R9+T9+AH9+AN9) | BA9: =IF($K9="","",IF(AND(K9="รย.1-เก๋ง 2 ตอน",OR(F9="Benz",F9="BMW",F9="Lexus",F9="Volvo")),F9,"อื่นๆ")) | BB9: =IF($K9="","",K9&"|"&BA9)
A10: =IF($K10="","",ROW()-1) | N10: =IF(OR(L10="",M10=""),"",IF(L10<>M10,"ใช่","ไม่ใช่")) | P10: =IF($K10="","",IF(O10="ตัดบัญชี",IFERROR(INDEX(Fee_ตัดบัญชี!$D:$D,MATCH(BB10,Fee_ตัดบัญชี!$C:$C,0)),0),0)) | Q10: =IF($K10="","",IF(O10="แจ้งย้าย",IFERROR(INDEX(Fee_แจ้งย้าย!$D:$D,MATCH(BB10,Fee_แจ้งย้าย!$C:$C,0)),0),0)) | R10: =IF($K10="","",IF(O10="แจ้งย้าย",5,0)) | T10: =IF($K10="","",IF(O10<>"ตัดบัญชี",0,IF(S10="กทม.",IFERROR(INDEX(Fee_ตรวจรถ_กทม!$D:$D,MATCH(BB10,Fee_ตรวจรถ_กทม!$C:$C,0)),0),IF(S10="ต่างจังหวัด",IFERROR(INDEX(Fee_ตรวจรถ_ตจว!$D:$D,MATCH(L10&"|"&K10,Fee_ตรวจรถ_ตจว!$C:$C,0)),0),0)))) | U10: =IF($K10="","",IF(LEFT(K10,5)="รย.12","รถจักรยานยนต์","รถยนต์")) | V10: =IF($K10="","",IF(U10="รถยนต์",IF(N10="ใช่",INDEX(Fee_รถยนต์_Bill!$B:$B,MATCH("ค่าคำขอ (ขอใช้จังหวัดอื่น)",Fee_รถยนต์_Bill!$A:$A,0)),INDEX(Fee_รถยนต์_Bill!$B:$B,MATCH("ค่าคำขอ (ปกติ)",Fee_รถยนต์_Bill!$A:$A,0))),IF(N10="ใช่",INDEX(Fee_จยย_Bill!$B:$B,MATCH("ค่าคำขอ (ขอใช้จังหวัดอื่น)",Fee_จยย_Bill!$A:$A,0)),INDEX(Fee_จยย_Bill!$B:$B,MATCH("ค่าคำขอ (ปกติ)",Fee_จยย_Bill!$A:$A,0))))) | W10: =IF($K10="","",IF(N10="ใช่",IF(U10="รถยนต์",INDEX(Fee_รถยนต์_Bill!$B:$B,MATCH("ค่าธรรมเนียมอื่นๆ (ขอใช้จังหวัดอื่น)",Fee_รถยนต์_Bill!$A:$A,0)),INDEX(Fee_จยย_Bill!$B:$B,MATCH("ค่าธรรมเนียมอื่นๆ (ขอใช้จังหวัดอื่น)",Fee_จยย_Bill!$A:$A,0))),0)) | X10: =IF($K10="","",IF(U10="รถยนต์",INDEX(Fee_รถยนต์_Bill!$B:$B,MATCH("ค่าตรวจสภาพรถ (Step4)",Fee_รถยนต์_Bill!$A:$A,0)),INDEX(Fee_จยย_Bill!$B:$B,MATCH("ค่าตรวจสภาพรถ (จยย.)",Fee_จยย_Bill!$A:$A,0)))) | Y10: =IF($K10="","",IF(U10="รถยนต์",INDEX(Fee_รถยนต์_Bill!$B:$B,MATCH("ค่าแผ่นป้ายทะเบียนรถ",Fee_รถยนต์_Bill!$A:$A,0)),INDEX(Fee_จยย_Bill!$B:$B,MATCH("ค่าแผ่นป้ายทะเบียน",Fee_จยย_Bill!$A:$A,0)))) | Z10: =IF($K10="","",IF(U10="รถยนต์",INDEX(Fee_รถยนต์_Bill!$B:$B,MATCH("ค่าใบคู่มือการจดทะเบียน",Fee_รถยนต์_Bill!$A:$A,0)),INDEX(Fee_จยย_Bill!$B:$B,MATCH("ค่าใบคู่มือจดทะเบียน",Fee_จยย_Bill!$A:$A,0)))) | AC10: =IF($K10="","",IF(AB10="เลขประมูล",INDEX(Fee_รถยนต์_Bill!$B:$B,MATCH("ค่าขอใช้เลขทะเบียน - เลขประมูล",Fee_รถยนต์_Bill!$A:$A,0)),IF(AB10="ไม่ใช่เลขประมูล",INDEX(Fee_รถยนต์_Bill!$B:$B,MATCH("ค่าขอใช้เลขทะเบียน - ไม่ใช่เลขประมูล",Fee_รถยนต์_Bill!$A:$A,0)),0))) | AE10: =IF($K10="","",IF(AD10="ป้ายขาวดำ",INDEX(Fee_รถยนต์_Bill!$B:$B,MATCH("ค่าทำแผ่นป้ายทะเบียนใหม่ - ป้ายขาวดำ",Fee_รถยนต์_Bill!$A:$A,0)),IF(AD10="ป้ายประมูล",INDEX(Fee_รถยนต์_Bill!$B:$B,MATCH("ค่าทำแผ่นป้ายทะเบียนใหม่ - ป้ายประมูล",Fee_รถยนต์_Bill!$A:$A,0)),0))) | AG10: =IF($K10="","",IF(AF10="ใช่",INDEX(Fee_รถยนต์_Bill!$B:$B,MATCH("ค่าย้ายออกต่างจังหวัด",Fee_รถยนต์_Bill!$A:$A,0)),0)) | AH10: =IF($K10="","",SUM(V10:AG10)) | AJ10: =IF($K10="","",IF(U10="รถยนต์",IF(AI10="ใช่",INDEX(Fee_รถยนต์_NoBill!$B:$B,MATCH("ค่าอากร (ทำเพิ่มเติมเกิน 1 รายการ)",Fee_รถยนต์_NoBill!$A:$A,0)),INDEX(Fee_รถยนต์_NoBill!$B:$B,MATCH("ค่าอากร (ปกติ)",Fee_รถยนต์_NoBill!$A:$A,0))),IF(AI10="ใช่",INDEX(Fee_จยย_NoBill!$B:$B,MATCH("ค่าอากร (ทำเพิ่มเติมเกิน 1 รายการ)",Fee_จยย_NoBill!$A:$A,0)),INDEX(Fee_จยย_NoBill!$B:$B,MATCH("ค่าอากร (ปกติ)",Fee_จยย_NoBill!$A:$A,0))))) | AK10: =IF($K10="","",IF(U10="รถยนต์",IFERROR(INDEX(Fee_รถยนต์_NoBill!$B:$B,MATCH("ลงขัน - "&K10,Fee_รถยนต์_NoBill!$A:$A,0)),0),IFERROR(INDEX(Fee_จยย_NoBill!$B:$B,MATCH("ลงขัน - รย.12 ทุกประเภท (CC)",Fee_จยย_NoBill!$A:$A,0)),0))) | AM10: =IF($K10="","",IF(AL10="ใช่",IF(U10="รถยนต์",INDEX(Fee_รถยนต์_NoBill!$B:$B,MATCH("งานด่วนเพิ่ม (ต่อคัน)",Fee_รถยนต์_NoBill!$A:$A,0)),INDEX(Fee_จยย_NoBill!$B:$B,MATCH("ลงขันด่วนเพิ่ม (ต่อคัน)",Fee_จยย_NoBill!$A:$A,0))),0)) | AN10: =IF($K10="","",SUM(AJ10:AM10)) | AO10: =IF($K10="","",P10+Q10+R10+T10+AH10+AN10) | BA10: =IF($K10="","",IF(AND(K10="รย.1-เก๋ง 2 ตอน",OR(F10="Benz",F10="BMW",F10="Lexus",F10="Volvo")),F10,"อื่นๆ")) | BB10: =IF($K10="","",K10&"|"&BA10)
A11: =IF($K11="","",ROW()-1) | N11: =IF(OR(L11="",M11=""),"",IF(L11<>M11,"ใช่","ไม่ใช่")) | P11: =IF($K11="","",IF(O11="ตัดบัญชี",IFERROR(INDEX(Fee_ตัดบัญชี!$D:$D,MATCH(BB11,Fee_ตัดบัญชี!$C:$C,0)),0),0)) | Q11: =IF($K11="","",IF(O11="แจ้งย้าย",IFERROR(INDEX(Fee_แจ้งย้าย!$D:$D,MATCH(BB11,Fee_แจ้งย้าย!$C:$C,0)),0),0)) | R11: =IF($K11="","",IF(O11="แจ้งย้าย",5,0)) | T11: =IF($K11="","",IF(O11<>"ตัดบัญชี",0,IF(S11="กทม.",IFERROR(INDEX(Fee_ตรวจรถ_กทม!$D:$D,MATCH(BB11,Fee_ตรวจรถ_กทม!$C:$C,0)),0),IF(S11="ต่างจังหวัด",IFERROR(INDEX(Fee_ตรวจรถ_ตจว!$D:$D,MATCH(L11&"|"&K11,Fee_ตรวจรถ_ตจว!$C:$C,0)),0),0)))) | U11: =IF($K11="","",IF(LEFT(K11,5)="รย.12","รถจักรยานยนต์","รถยนต์")) | V11: =IF($K11="","",IF(U11="รถยนต์",IF(N11="ใช่",INDEX(Fee_รถยนต์_Bill!$B:$B,MATCH("ค่าคำขอ (ขอใช้จังหวัดอื่น)",Fee_รถยนต์_Bill!$A:$A,0)),INDEX(Fee_รถยนต์_Bill!$B:$B,MATCH("ค่าคำขอ (ปกติ)",Fee_รถยนต์_Bill!$A:$A,0))),IF(N11="ใช่",INDEX(Fee_จยย_Bill!$B:$B,MATCH("ค่าคำขอ (ขอใช้จังหวัดอื่น)",Fee_จยย_Bill!$A:$A,0)),INDEX(Fee_จยย_Bill!$B:$B,MATCH("ค่าคำขอ (ปกติ)",Fee_จยย_Bill!$A:$A,0))))) | W11: =IF($K11="","",IF(N11="ใช่",IF(U11="รถยนต์",INDEX(Fee_รถยนต์_Bill!$B:$B,MATCH("ค่าธรรมเนียมอื่นๆ (ขอใช้จังหวัดอื่น)",Fee_รถยนต์_Bill!$A:$A,0)),INDEX(Fee_จยย_Bill!$B:$B,MATCH("ค่าธรรมเนียมอื่นๆ (ขอใช้จังหวัดอื่น)",Fee_จยย_Bill!$A:$A,0))),0)) | X11: =IF($K11="","",IF(U11="รถยนต์",INDEX(Fee_รถยนต์_Bill!$B:$B,MATCH("ค่าตรวจสภาพรถ (Step4)",Fee_รถยนต์_Bill!$A:$A,0)),INDEX(Fee_จยย_Bill!$B:$B,MATCH("ค่าตรวจสภาพรถ (จยย.)",Fee_จยย_Bill!$A:$A,0)))) | Y11: =IF($K11="","",IF(U11="รถยนต์",INDEX(Fee_รถยนต์_Bill!$B:$B,MATCH("ค่าแผ่นป้ายทะเบียนรถ",Fee_รถยนต์_Bill!$A:$A,0)),INDEX(Fee_จยย_Bill!$B:$B,MATCH("ค่าแผ่นป้ายทะเบียน",Fee_จยย_Bill!$A:$A,0)))) | Z11: =IF($K11="","",IF(U11="รถยนต์",INDEX(Fee_รถยนต์_Bill!$B:$B,MATCH("ค่าใบคู่มือการจดทะเบียน",Fee_รถยนต์_Bill!$A:$A,0)),INDEX(Fee_จยย_Bill!$B:$B,MATCH("ค่าใบคู่มือจดทะเบียน",Fee_จยย_Bill!$A:$A,0)))) | AC11: =IF($K11="","",IF(AB11="เลขประมูล",INDEX(Fee_รถยนต์_Bill!$B:$B,MATCH("ค่าขอใช้เลขทะเบียน - เลขประมูล",Fee_รถยนต์_Bill!$A:$A,0)),IF(AB11="ไม่ใช่เลขประมูล",INDEX(Fee_รถยนต์_Bill!$B:$B,MATCH("ค่าขอใช้เลขทะเบียน - ไม่ใช่เลขประมูล",Fee_รถยนต์_Bill!$A:$A,0)),0))) | AE11: =IF($K11="","",IF(AD11="ป้ายขาวดำ",INDEX(Fee_รถยนต์_Bill!$B:$B,MATCH("ค่าทำแผ่นป้ายทะเบียนใหม่ - ป้ายขาวดำ",Fee_รถยนต์_Bill!$A:$A,0)),IF(AD11="ป้ายประมูล",INDEX(Fee_รถยนต์_Bill!$B:$B,MATCH("ค่าทำแผ่นป้ายทะเบียนใหม่ - ป้ายประมูล",Fee_รถยนต์_Bill!$A:$A,0)),0))) | AG11: =IF($K11="","",IF(AF11="ใช่",INDEX(Fee_รถยนต์_Bill!$B:$B,MATCH("ค่าย้ายออกต่างจังหวัด",Fee_รถยนต์_Bill!$A:$A,0)),0)) | AH11: =IF($K11="","",SUM(V11:AG11)) | AJ11: =IF($K11="","",IF(U11="รถยนต์",IF(AI11="ใช่",INDEX(Fee_รถยนต์_NoBill!$B:$B,MATCH("ค่าอากร (ทำเพิ่มเติมเกิน 1 รายการ)",Fee_รถยนต์_NoBill!$A:$A,0)),INDEX(Fee_รถยนต์_NoBill!$B:$B,MATCH("ค่าอากร (ปกติ)",Fee_รถยนต์_NoBill!$A:$A,0))),IF(AI11="ใช่",INDEX(Fee_จยย_NoBill!$B:$B,MATCH("ค่าอากร (ทำเพิ่มเติมเกิน 1 รายการ)",Fee_จยย_NoBill!$A:$A,0)),INDEX(Fee_จยย_NoBill!$B:$B,MATCH("ค่าอากร (ปกติ)",Fee_จยย_NoBill!$A:$A,0))))) | AK11: =IF($K11="","",IF(U11="รถยนต์",IFERROR(INDEX(Fee_รถยนต์_NoBill!$B:$B,MATCH("ลงขัน - "&K11,Fee_รถยนต์_NoBill!$A:$A,0)),0),IFERROR(INDEX(Fee_จยย_NoBill!$B:$B,MATCH("ลงขัน - รย.12 ทุกประเภท (CC)",Fee_จยย_NoBill!$A:$A,0)),0))) | AM11: =IF($K11="","",IF(AL11="ใช่",IF(U11="รถยนต์",INDEX(Fee_รถยนต์_NoBill!$B:$B,MATCH("งานด่วนเพิ่ม (ต่อคัน)",Fee_รถยนต์_NoBill!$A:$A,0)),INDEX(Fee_จยย_NoBill!$B:$B,MATCH("ลงขันด่วนเพิ่ม (ต่อคัน)",Fee_จยย_NoBill!$A:$A,0))),0)) | AN11: =IF($K11="","",SUM(AJ11:AM11)) | AO11: =IF($K11="","",P11+Q11+R11+T11+AH11+AN11) | BA11: =IF($K11="","",IF(AND(K11="รย.1-เก๋ง 2 ตอน",OR(F11="Benz",F11="BMW",F11="Lexus",F11="Volvo")),F11,"อื่นๆ")) | BB11: =IF($K11="","",K11&"|"&BA11)
A12: =IF($K12="","",ROW()-1) | N12: =IF(OR(L12="",M12=""),"",IF(L12<>M12,"ใช่","ไม่ใช่")) | P12: =IF($K12="","",IF(O12="ตัดบัญชี",IFERROR(INDEX(Fee_ตัดบัญชี!$D:$D,MATCH(BB12,Fee_ตัดบัญชี!$C:$C,0)),0),0)) | Q12: =IF($K12="","",IF(O12="แจ้งย้าย",IFERROR(INDEX(Fee_แจ้งย้าย!$D:$D,MATCH(BB12,Fee_แจ้งย้าย!$C:$C,0)),0),0)) | R12: =IF($K12="","",IF(O12="แจ้งย้าย",5,0)) | T12: =IF($K12="","",IF(O12<>"ตัดบัญชี",0,IF(S12="กทม.",IFERROR(INDEX(Fee_ตรวจรถ_กทม!$D:$D,MATCH(BB12,Fee_ตรวจรถ_กทม!$C:$C,0)),0),IF(S12="ต่างจังหวัด",IFERROR(INDEX(Fee_ตรวจรถ_ตจว!$D:$D,MATCH(L12&"|"&K12,Fee_ตรวจรถ_ตจว!$C:$C,0)),0),0)))) | U12: =IF($K12="","",IF(LEFT(K12,5)="รย.12","รถจักรยานยนต์","รถยนต์")) | V12: =IF($K12="","",IF(U12="รถยนต์",IF(N12="ใช่",INDEX(Fee_รถยนต์_Bill!$B:$B,MATCH("ค่าคำขอ (ขอใช้จังหวัดอื่น)",Fee_รถยนต์_Bill!$A:$A,0)),INDEX(Fee_รถยนต์_Bill!$B:$B,MATCH("ค่าคำขอ (ปกติ)",Fee_รถยนต์_Bill!$A:$A,0))),IF(N12="ใช่",INDEX(Fee_จยย_Bill!$B:$B,MATCH("ค่าคำขอ (ขอใช้จังหวัดอื่น)",Fee_จยย_Bill!$A:$A,0)),INDEX(Fee_จยย_Bill!$B:$B,MATCH("ค่าคำขอ (ปกติ)",Fee_จยย_Bill!$A:$A,0))))) | W12: =IF($K12="","",IF(N12="ใช่",IF(U12="รถยนต์",INDEX(Fee_รถยนต์_Bill!$B:$B,MATCH("ค่าธรรมเนียมอื่นๆ (ขอใช้จังหวัดอื่น)",Fee_รถยนต์_Bill!$A:$A,0)),INDEX(Fee_จยย_Bill!$B:$B,MATCH("ค่าธรรมเนียมอื่นๆ (ขอใช้จังหวัดอื่น)",Fee_จยย_Bill!$A:$A,0))),0)) | X12: =IF($K12="","",IF(U12="รถยนต์",INDEX(Fee_รถยนต์_Bill!$B:$B,MATCH("ค่าตรวจสภาพรถ (Step4)",Fee_รถยนต์_Bill!$A:$A,0)),INDEX(Fee_จยย_Bill!$B:$B,MATCH("ค่าตรวจสภาพรถ (จยย.)",Fee_จยย_Bill!$A:$A,0)))) | Y12: =IF($K12="","",IF(U12="รถยนต์",INDEX(Fee_รถยนต์_Bill!$B:$B,MATCH("ค่าแผ่นป้ายทะเบียนรถ",Fee_รถยนต์_Bill!$A:$A,0)),INDEX(Fee_จยย_Bill!$B:$B,MATCH("ค่าแผ่นป้ายทะเบียน",Fee_จยย_Bill!$A:$A,0)))) | Z12: =IF($K12="","",IF(U12="รถยนต์",INDEX(Fee_รถยนต์_Bill!$B:$B,MATCH("ค่าใบคู่มือการจดทะเบียน",Fee_รถยนต์_Bill!$A:$A,0)),INDEX(Fee_จยย_Bill!$B:$B,MATCH("ค่าใบคู่มือจดทะเบียน",Fee_จยย_Bill!$A:$A,0)))) | AC12: =IF($K12="","",IF(AB12="เลขประมูล",INDEX(Fee_รถยนต์_Bill!$B:$B,MATCH("ค่าขอใช้เลขทะเบียน - เลขประมูล",Fee_รถยนต์_Bill!$A:$A,0)),IF(AB12="ไม่ใช่เลขประมูล",INDEX(Fee_รถยนต์_Bill!$B:$B,MATCH("ค่าขอใช้เลขทะเบียน - ไม่ใช่เลขประมูล",Fee_รถยนต์_Bill!$A:$A,0)),0))) | AE12: =IF($K12="","",IF(AD12="ป้ายขาวดำ",INDEX(Fee_รถยนต์_Bill!$B:$B,MATCH("ค่าทำแผ่นป้ายทะเบียนใหม่ - ป้ายขาวดำ",Fee_รถยนต์_Bill!$A:$A,0)),IF(AD12="ป้ายประมูล",INDEX(Fee_รถยนต์_Bill!$B:$B,MATCH("ค่าทำแผ่นป้ายทะเบียนใหม่ - ป้ายประมูล",Fee_รถยนต์_Bill!$A:$A,0)),0))) | AG12: =IF($K12="","",IF(AF12="ใช่",INDEX(Fee_รถยนต์_Bill!$B:$B,MATCH("ค่าย้ายออกต่างจังหวัด",Fee_รถยนต์_Bill!$A:$A,0)),0)) | AH12: =IF($K12="","",SUM(V12:AG12)) | AJ12: =IF($K12="","",IF(U12="รถยนต์",IF(AI12="ใช่",INDEX(Fee_รถยนต์_NoBill!$B:$B,MATCH("ค่าอากร (ทำเพิ่มเติมเกิน 1 รายการ)",Fee_รถยนต์_NoBill!$A:$A,0)),INDEX(Fee_รถยนต์_NoBill!$B:$B,MATCH("ค่าอากร (ปกติ)",Fee_รถยนต์_NoBill!$A:$A,0))),IF(AI12="ใช่",INDEX(Fee_จยย_NoBill!$B:$B,MATCH("ค่าอากร (ทำเพิ่มเติมเกิน 1 รายการ)",Fee_จยย_NoBill!$A:$A,0)),INDEX(Fee_จยย_NoBill!$B:$B,MATCH("ค่าอากร (ปกติ)",Fee_จยย_NoBill!$A:$A,0))))) | AK12: =IF($K12="","",IF(U12="รถยนต์",IFERROR(INDEX(Fee_รถยนต์_NoBill!$B:$B,MATCH("ลงขัน - "&K12,Fee_รถยนต์_NoBill!$A:$A,0)),0),IFERROR(INDEX(Fee_จยย_NoBill!$B:$B,MATCH("ลงขัน - รย.12 ทุกประเภท (CC)",Fee_จยย_NoBill!$A:$A,0)),0))) | AM12: =IF($K12="","",IF(AL12="ใช่",IF(U12="รถยนต์",INDEX(Fee_รถยนต์_NoBill!$B:$B,MATCH("งานด่วนเพิ่ม (ต่อคัน)",Fee_รถยนต์_NoBill!$A:$A,0)),INDEX(Fee_จยย_NoBill!$B:$B,MATCH("ลงขันด่วนเพิ่ม (ต่อคัน)",Fee_จยย_NoBill!$A:$A,0))),0)) | AN12: =IF($K12="","",SUM(AJ12:AM12)) | AO12: =IF($K12="","",P12+Q12+R12+T12+AH12+AN12) | BA12: =IF($K12="","",IF(AND(K12="รย.1-เก๋ง 2 ตอน",OR(F12="Benz",F12="BMW",F12="Lexus",F12="Volvo")),F12,"อื่นๆ")) | BB12: =IF($K12="","",K12&"|"&BA12)
A13: =IF($K13="","",ROW()-1) | N13: =IF(OR(L13="",M13=""),"",IF(L13<>M13,"ใช่","ไม่ใช่")) | P13: =IF($K13="","",IF(O13="ตัดบัญชี",IFERROR(INDEX(Fee_ตัดบัญชี!$D:$D,MATCH(BB13,Fee_ตัดบัญชี!$C:$C,0)),0),0)) | Q13: =IF($K13="","",IF(O13="แจ้งย้าย",IFERROR(INDEX(Fee_แจ้งย้าย!$D:$D,MATCH(BB13,Fee_แจ้งย้าย!$C:$C,0)),0),0)) | R13: =IF($K13="","",IF(O13="แจ้งย้าย",5,0)) | T13: =IF($K13="","",IF(O13<>"ตัดบัญชี",0,IF(S13="กทม.",IFERROR(INDEX(Fee_ตรวจรถ_กทม!$D:$D,MATCH(BB13,Fee_ตรวจรถ_กทม!$C:$C,0)),0),IF(S13="ต่างจังหวัด",IFERROR(INDEX(Fee_ตรวจรถ_ตจว!$D:$D,MATCH(L13&"|"&K13,Fee_ตรวจรถ_ตจว!$C:$C,0)),0),0)))) | U13: =IF($K13="","",IF(LEFT(K13,5)="รย.12","รถจักรยานยนต์","รถยนต์")) | V13: =IF($K13="","",IF(U13="รถยนต์",IF(N13="ใช่",INDEX(Fee_รถยนต์_Bill!$B:$B,MATCH("ค่าคำขอ (ขอใช้จังหวัดอื่น)",Fee_รถยนต์_Bill!$A:$A,0)),INDEX(Fee_รถยนต์_Bill!$B:$B,MATCH("ค่าคำขอ (ปกติ)",Fee_รถยนต์_Bill!$A:$A,0))),IF(N13="ใช่",INDEX(Fee_จยย_Bill!$B:$B,MATCH("ค่าคำขอ (ขอใช้จังหวัดอื่น)",Fee_จยย_Bill!$A:$A,0)),INDEX(Fee_จยย_Bill!$B:$B,MATCH("ค่าคำขอ (ปกติ)",Fee_จยย_Bill!$A:$A,0))))) | W13: =IF($K13="","",IF(N13="ใช่",IF(U13="รถยนต์",INDEX(Fee_รถยนต์_Bill!$B:$B,MATCH("ค่าธรรมเนียมอื่นๆ (ขอใช้จังหวัดอื่น)",Fee_รถยนต์_Bill!$A:$A,0)),INDEX(Fee_จยย_Bill!$B:$B,MATCH("ค่าธรรมเนียมอื่นๆ (ขอใช้จังหวัดอื่น)",Fee_จยย_Bill!$A:$A,0))),0)) | X13: =IF($K13="","",IF(U13="รถยนต์",INDEX(Fee_รถยนต์_Bill!$B:$B,MATCH("ค่าตรวจสภาพรถ (Step4)",Fee_รถยนต์_Bill!$A:$A,0)),INDEX(Fee_จยย_Bill!$B:$B,MATCH("ค่าตรวจสภาพรถ (จยย.)",Fee_จยย_Bill!$A:$A,0)))) | Y13: =IF($K13="","",IF(U13="รถยนต์",INDEX(Fee_รถยนต์_Bill!$B:$B,MATCH("ค่าแผ่นป้ายทะเบียนรถ",Fee_รถยนต์_Bill!$A:$A,0)),INDEX(Fee_จยย_Bill!$B:$B,MATCH("ค่าแผ่นป้ายทะเบียน",Fee_จยย_Bill!$A:$A,0)))) | Z13: =IF($K13="","",IF(U13="รถยนต์",INDEX(Fee_รถยนต์_Bill!$B:$B,MATCH("ค่าใบคู่มือการจดทะเบียน",Fee_รถยนต์_Bill!$A:$A,0)),INDEX(Fee_จยย_Bill!$B:$B,MATCH("ค่าใบคู่มือจดทะเบียน",Fee_จยย_Bill!$A:$A,0)))) | AC13: =IF($K13="","",IF(AB13="เลขประมูล",INDEX(Fee_รถยนต์_Bill!$B:$B,MATCH("ค่าขอใช้เลขทะเบียน - เลขประมูล",Fee_รถยนต์_Bill!$A:$A,0)),IF(AB13="ไม่ใช่เลขประมูล",INDEX(Fee_รถยนต์_Bill!$B:$B,MATCH("ค่าขอใช้เลขทะเบียน - ไม่ใช่เลขประมูล",Fee_รถยนต์_Bill!$A:$A,0)),0))) | AE13: =IF($K13="","",IF(AD13="ป้ายขาวดำ",INDEX(Fee_รถยนต์_Bill!$B:$B,MATCH("ค่าทำแผ่นป้ายทะเบียนใหม่ - ป้ายขาวดำ",Fee_รถยนต์_Bill!$A:$A,0)),IF(AD13="ป้ายประมูล",INDEX(Fee_รถยนต์_Bill!$B:$B,MATCH("ค่าทำแผ่นป้ายทะเบียนใหม่ - ป้ายประมูล",Fee_รถยนต์_Bill!$A:$A,0)),0))) | AG13: =IF($K13="","",IF(AF13="ใช่",INDEX(Fee_รถยนต์_Bill!$B:$B,MATCH("ค่าย้ายออกต่างจังหวัด",Fee_รถยนต์_Bill!$A:$A,0)),0)) | AH13: =IF($K13="","",SUM(V13:AG13)) | AJ13: =IF($K13="","",IF(U13="รถยนต์",IF(AI13="ใช่",INDEX(Fee_รถยนต์_NoBill!$B:$B,MATCH("ค่าอากร (ทำเพิ่มเติมเกิน 1 รายการ)",Fee_รถยนต์_NoBill!$A:$A,0)),INDEX(Fee_รถยนต์_NoBill!$B:$B,MATCH("ค่าอากร (ปกติ)",Fee_รถยนต์_NoBill!$A:$A,0))),IF(AI13="ใช่",INDEX(Fee_จยย_NoBill!$B:$B,MATCH("ค่าอากร (ทำเพิ่มเติมเกิน 1 รายการ)",Fee_จยย_NoBill!$A:$A,0)),INDEX(Fee_จยย_NoBill!$B:$B,MATCH("ค่าอากร (ปกติ)",Fee_จยย_NoBill!$A:$A,0))))) | AK13: =IF($K13="","",IF(U13="รถยนต์",IFERROR(INDEX(Fee_รถยนต์_NoBill!$B:$B,MATCH("ลงขัน - "&K13,Fee_รถยนต์_NoBill!$A:$A,0)),0),IFERROR(INDEX(Fee_จยย_NoBill!$B:$B,MATCH("ลงขัน - รย.12 ทุกประเภท (CC)",Fee_จยย_NoBill!$A:$A,0)),0))) | AM13: =IF($K13="","",IF(AL13="ใช่",IF(U13="รถยนต์",INDEX(Fee_รถยนต์_NoBill!$B:$B,MATCH("งานด่วนเพิ่ม (ต่อคัน)",Fee_รถยนต์_NoBill!$A:$A,0)),INDEX(Fee_จยย_NoBill!$B:$B,MATCH("ลงขันด่วนเพิ่ม (ต่อคัน)",Fee_จยย_NoBill!$A:$A,0))),0)) | AN13: =IF($K13="","",SUM(AJ13:AM13)) | AO13: =IF($K13="","",P13+Q13+R13+T13+AH13+AN13) | BA13: =IF($K13="","",IF(AND(K13="รย.1-เก๋ง 2 ตอน",OR(F13="Benz",F13="BMW",F13="Lexus",F13="Volvo")),F13,"อื่นๆ")) | BB13: =IF($K13="","",K13&"|"&BA13)
A14: =IF($K14="","",ROW()-1) | N14: =IF(OR(L14="",M14=""),"",IF(L14<>M14,"ใช่","ไม่ใช่")) | P14: =IF($K14="","",IF(O14="ตัดบัญชี",IFERROR(INDEX(Fee_ตัดบัญชี!$D:$D,MATCH(BB14,Fee_ตัดบัญชี!$C:$C,0)),0),0)) | Q14: =IF($K14="","",IF(O14="แจ้งย้าย",IFERROR(INDEX(Fee_แจ้งย้าย!$D:$D,MATCH(BB14,Fee_แจ้งย้าย!$C:$C,0)),0),0)) | R14: =IF($K14="","",IF(O14="แจ้งย้าย",5,0)) | T14: =IF($K14="","",IF(O14<>"ตัดบัญชี",0,IF(S14="กทม.",IFERROR(INDEX(Fee_ตรวจรถ_กทม!$D:$D,MATCH(BB14,Fee_ตรวจรถ_กทม!$C:$C,0)),0),IF(S14="ต่างจังหวัด",IFERROR(INDEX(Fee_ตรวจรถ_ตจว!$D:$D,MATCH(L14&"|"&K14,Fee_ตรวจรถ_ตจว!$C:$C,0)),0),0)))) | U14: =IF($K14="","",IF(LEFT(K14,5)="รย.12","รถจักรยานยนต์","รถยนต์")) | V14: =IF($K14="","",IF(U14="รถยนต์",IF(N14="ใช่",INDEX(Fee_รถยนต์_Bill!$B:$B,MATCH("ค่าคำขอ (ขอใช้จังหวัดอื่น)",Fee_รถยนต์_Bill!$A:$A,0)),INDEX(Fee_รถยนต์_Bill!$B:$B,MATCH("ค่าคำขอ (ปกติ)",Fee_รถยนต์_Bill!$A:$A,0))),IF(N14="ใช่",INDEX(Fee_จยย_Bill!$B:$B,MATCH("ค่าคำขอ (ขอใช้จังหวัดอื่น)",Fee_จยย_Bill!$A:$A,0)),INDEX(Fee_จยย_Bill!$B:$B,MATCH("ค่าคำขอ (ปกติ)",Fee_จยย_Bill!$A:$A,0))))) | W14: =IF($K14="","",IF(N14="ใช่",IF(U14="รถยนต์",INDEX(Fee_รถยนต์_Bill!$B:$B,MATCH("ค่าธรรมเนียมอื่นๆ (ขอใช้จังหวัดอื่น)",Fee_รถยนต์_Bill!$A:$A,0)),INDEX(Fee_จยย_Bill!$B:$B,MATCH("ค่าธรรมเนียมอื่นๆ (ขอใช้จังหวัดอื่น)",Fee_จยย_Bill!$A:$A,0))),0)) | X14: =IF($K14="","",IF(U14="รถยนต์",INDEX(Fee_รถยนต์_Bill!$B:$B,MATCH("ค่าตรวจสภาพรถ (Step4)",Fee_รถยนต์_Bill!$A:$A,0)),INDEX(Fee_จยย_Bill!$B:$B,MATCH("ค่าตรวจสภาพรถ (จยย.)",Fee_จยย_Bill!$A:$A,0)))) | Y14: =IF($K14="","",IF(U14="รถยนต์",INDEX(Fee_รถยนต์_Bill!$B:$B,MATCH("ค่าแผ่นป้ายทะเบียนรถ",Fee_รถยนต์_Bill!$A:$A,0)),INDEX(Fee_จยย_Bill!$B:$B,MATCH("ค่าแผ่นป้ายทะเบียน",Fee_จยย_Bill!$A:$A,0)))) | Z14: =IF($K14="","",IF(U14="รถยนต์",INDEX(Fee_รถยนต์_Bill!$B:$B,MATCH("ค่าใบคู่มือการจดทะเบียน",Fee_รถยนต์_Bill!$A:$A,0)),INDEX(Fee_จยย_Bill!$B:$B,MATCH("ค่าใบคู่มือจดทะเบียน",Fee_จยย_Bill!$A:$A,0)))) | AC14: =IF($K14="","",IF(AB14="เลขประมูล",INDEX(Fee_รถยนต์_Bill!$B:$B,MATCH("ค่าขอใช้เลขทะเบียน - เลขประมูล",Fee_รถยนต์_Bill!$A:$A,0)),IF(AB14="ไม่ใช่เลขประมูล",INDEX(Fee_รถยนต์_Bill!$B:$B,MATCH("ค่าขอใช้เลขทะเบียน - ไม่ใช่เลขประมูล",Fee_รถยนต์_Bill!$A:$A,0)),0))) | AE14: =IF($K14="","",IF(AD14="ป้ายขาวดำ",INDEX(Fee_รถยนต์_Bill!$B:$B,MATCH("ค่าทำแผ่นป้ายทะเบียนใหม่ - ป้ายขาวดำ",Fee_รถยนต์_Bill!$A:$A,0)),IF(AD14="ป้ายประมูล",INDEX(Fee_รถยนต์_Bill!$B:$B,MATCH("ค่าทำแผ่นป้ายทะเบียนใหม่ - ป้ายประมูล",Fee_รถยนต์_Bill!$A:$A,0)),0))) | AG14: =IF($K14="","",IF(AF14="ใช่",INDEX(Fee_รถยนต์_Bill!$B:$B,MATCH("ค่าย้ายออกต่างจังหวัด",Fee_รถยนต์_Bill!$A:$A,0)),0)) | AH14: =IF($K14="","",SUM(V14:AG14)) | AJ14: =IF($K14="","",IF(U14="รถยนต์",IF(AI14="ใช่",INDEX(Fee_รถยนต์_NoBill!$B:$B,MATCH("ค่าอากร (ทำเพิ่มเติมเกิน 1 รายการ)",Fee_รถยนต์_NoBill!$A:$A,0)),INDEX(Fee_รถยนต์_NoBill!$B:$B,MATCH("ค่าอากร (ปกติ)",Fee_รถยนต์_NoBill!$A:$A,0))),IF(AI14="ใช่",INDEX(Fee_จยย_NoBill!$B:$B,MATCH("ค่าอากร (ทำเพิ่มเติมเกิน 1 รายการ)",Fee_จยย_NoBill!$A:$A,0)),INDEX(Fee_จยย_NoBill!$B:$B,MATCH("ค่าอากร (ปกติ)",Fee_จยย_NoBill!$A:$A,0))))) | AK14: =IF($K14="","",IF(U14="รถยนต์",IFERROR(INDEX(Fee_รถยนต์_NoBill!$B:$B,MATCH("ลงขัน - "&K14,Fee_รถยนต์_NoBill!$A:$A,0)),0),IFERROR(INDEX(Fee_จยย_NoBill!$B:$B,MATCH("ลงขัน - รย.12 ทุกประเภท (CC)",Fee_จยย_NoBill!$A:$A,0)),0))) | AM14: =IF($K14="","",IF(AL14="ใช่",IF(U14="รถยนต์",INDEX(Fee_รถยนต์_NoBill!$B:$B,MATCH("งานด่วนเพิ่ม (ต่อคัน)",Fee_รถยนต์_NoBill!$A:$A,0)),INDEX(Fee_จยย_NoBill!$B:$B,MATCH("ลงขันด่วนเพิ่ม (ต่อคัน)",Fee_จยย_NoBill!$A:$A,0))),0)) | AN14: =IF($K14="","",SUM(AJ14:AM14)) | AO14: =IF($K14="","",P14+Q14+R14+T14+AH14+AN14) | BA14: =IF($K14="","",IF(AND(K14="รย.1-เก๋ง 2 ตอน",OR(F14="Benz",F14="BMW",F14="Lexus",F14="Volvo")),F14,"อื่นๆ")) | BB14: =IF($K14="","",K14&"|"&BA14)
